Workbook

Sheet 1_Cables_Completo
A1: TAG_CABLE | B1: DE (From) | C1: HACIA (To) | D1: TENSION_V | E1: LONGITUD_m | F1: CONST | G1: FORMACION | H1: AREA | I1: DESCRIPCION | J1: TIPO | K1: CPF | L1: COND/ PUNTA | M1: ARMADO (SI/NO) | N1: PTAS COND | O1: PTAS ARM | P1: TOTAL PTAS | Q1: TIPO CABLE | R1: TIPO CARGA
A2: P-670-CP-600J | B2: 670-TGBT-001 | C2: TCA10-GE-10 | D2: 380 | E2: 75 | F2: 1kV-XLPE-Arm-CU | G2: 3x25/16 | H2: SALA ELÉCTRICA GENERACIÓN | I2: Tablero de control KBE-600J (G10\ (28 Kw CPF1\ 0 | J2: POTENCIA_BT | K2: CPF1 | L2: 4 | M2: SI | N2: 8 | O2: 2 | P2: 10 | Q2: POTENCIA BT PEQUEÑA (10-25mm²) | R2: TABLERO/CCM
A3: P-670-CP-600K | B3: 670-TGBT-001 | C3: TCA11-GE-11 | D3: 380 | E3: 75 | F3: 1kV-XLPE-Arm-CU | G3: 3x25/16 | H3: SALA ELÉCTRICA GENERACIÓN | I3: Tablero de control KBE-600K (G11\ (28 kW CPF1\ 0 | J3: POTENCIA_BT | K3: CPF1 | L3: 4 | M3: SI | N3: 8 | O3: 2 | P3: 10 | Q3: POTENCIA BT PEQUEÑA (10-25mm²) | R3: TABLERO/CCM
A4: P-SKZZ-67040A | B4: 670-TGBT-001 | C4: SKZZ-67040A | D4: 380 | E4: 100 | F4: 1kV-XLPE-Arm-CU | G4: 3x35/16 | H4: SALA ELÉCTRICA GENERACIÓN | I4: CALENTADOR DE GAS COMBUSTIBLE 0 | J4: POTENCIA_BT | K4: CPF1 | L4: 4 | M4: SI | N4: 8 | O4: 2 | P4: 10 | Q4: POTENCIA BT MEDIANA (35-70mm²) | R4: TABLERO/CCM
A5: P-SKZZ-67040B | B5: 670-TGBT-001 | C5: SKZZ-67040B | D5: 380 | E5: 100 | F5: 1kV-XLPE-Arm-CU | G5: 3x35/16 | H5: SALA ELÉCTRICA GENERACIÓN | I5: CALENTADOR DE GAS COMBUSTIBLE 0 | J5: POTENCIA_BT | K5: CPF1 | L5: 4 | M5: SI | N5: 8 | O5: 2 | P5: 10 | Q5: POTENCIA BT MEDIANA (35-70mm²) | R5: TABLERO/CCM
A6: P-SKZZ-90215 | B6: 670-TGBT-001 | C6: SKZZ-90215 | D6: 380 | E6: 130 | F6: 1kV-XLPE-Arm-CU | G6: 4x4 | H6: SALA ELÉCTRICA GENERACIÓN | I6: SKID INHIBIDOR DE HIDRATOS 670-DP-001 (Tab de SSAA\ | J6: POTENCIA_BT | K6: CPF1 | L6: 4 | M6: SI | N6: 8 | O6: 2 | P6: 10 | Q6: POTENCIA BT MUY PEQ (<10mm²) | R6: TABLERO/CCM
A7: P-JBT-SKZZ-67040 | B7: 670-DP-001 | C7: JBT-SKZZ-67040 | D7: 220 | E7: 100 | F7: 1kV-XLPE-Arm-T-CU | G7: 2x4+T | H7: SALA ELÉCTRICA GENERACIÓN | I7: TRACING SKID CALENTADORES DE GAS COMBUSTIBLE 0 | J7: POTENCIA_BT | K7: CPF1 | L7: 3 | M7: SI | N7: 6 | O7: 2 | P7: 8 | Q7: POTENCIA BT MUY PEQ (<10mm²) | R7: CALEFACCION/TRAZADO
A8: P-KBE600J-AUX1 | B8: 670-DP-001 | C8: KBE600J-AUX1 | D8: 220 | E8: 75 | F8: 1kV-XLPE-Arm-CU | G8: 2x4 | H8: SALA ELÉCTRICA GENERACIÓN | I8: Servicios Aux. bahia generador KBE-600J (G10\ 0 | J8: POTENCIA_BT | K8: CPF1 | L8: 2 | M8: SI | N8: 4 | O8: 2 | P8: 6 | Q8: POTENCIA BT MUY PEQ (<10mm²) | R8: TABLERO/CCM
A9: P-KBE600K-AUX1 | B9: 670-DP-001 | C9: KBE600K-AUX1 | D9: 220 | E9: 75 | F9: 1kV-XLPE-Arm-CU | G9: 2x4 | H9: SALA ELÉCTRICA GENERACIÓN | I9: Servicios Aux. bahia generador KBE-600K (G11\ 670-DP-101VCC | J9: POTENCIA_BT | K9: CPF1 | L9: 2 | M9: SI | N9: 4 | O9: 2 | P9: 6 | Q9: POTENCIA BT MUY PEQ (<10mm²) | R9: UPS/RECTIF/SSAA
A10: P-KBE600J-AUX2 | B10: 670-DP-101VCC | C10: KBE600J-AUX2 | D10: 110 | E10: 75 | F10: 1kV-XLPE-Arm-CU | G10: 2x4 | H10: SALA ELÉCTRICA GENERACIÓN | I10: Sistema Aux. bahia generador KBE-600J (G10\ 0 | J10: CONTROL | K10: CPF1 | L10: 2 | M10: SI | N10: 4 | O10: 2 | P10: 6 | Q10: CONTROL | R10: TABLERO/CCM
A11: P-KBE600K-AUX2 | B11: 670-DP-101VCC | C11: KBE600K-AUX2 | D11: 110 | E11: 75 | F11: 1kV-XLPE-Arm-CU | G11: 2x4 | H11: SALA ELÉCTRICA GENERACIÓN | I11: Sistema Aux. bahia generador KBE-600K (G11\ 670-DP-001UPS | J11: CONTROL | K11: CPF1 | L11: 2 | M11: SI | N11: 4 | O11: 2 | P11: 6 | Q11: CONTROL | R11: UPS/RECTIF/SSAA
A12: P-PLC-EAP-67040A | B12: 670-DP-001UPS | C12: PLC-EAP-67040A | D12: 220 | E12: 100 | F12: 1kV-XLPE-Arm-CU | G12: 2x4 | H12: SALA ELÉCTRICA GENERACIÓN | J12: POTENCIA_BT | K12: CPF1 | L12: 2 | M12: SI | N12: 4 | O12: 2 | P12: 6 | Q12: POTENCIA BT MUY PEQ (<10mm²) | R12: TABLERO/CCM
A13: P-PLC-EAP-67040B | B13: 670-DP-001UPS | C13: PLC-EAP-67040B | D13: 220 | E13: 100 | F13: 1kV-XLPE-Arm-CU | G13: 2x4 | H13: SALA ELÉCTRICA GENERACIÓN | J13: POTENCIA_BT | K13: CPF1 | L13: 2 | M13: SI | N13: 4 | O13: 2 | P13: 6 | Q13: POTENCIA BT MUY PEQ (<10mm²) | R13: TABLERO/CCM
A14: FO-102-PMS-101 | B14: 670-PMS-001 | C14: 102-PMS-101 | D14: - | E14: 400 | F14: F.O. monomodo | G14: F.O. | H14: SALA ELÉCTRICA GENERACIÓN | I14: Ampliación Red de control hacia SE#4 | J14: FO | K14: CPF2 | L14: 2 | M14: NO | N14: 4 | O14: 0 | P14: 4 | Q14: FO / ETHERNET | R14: CONTROL
A15: C-GE10-TMC-01-1 | B15: TCA10-GE-10 | C15: TMC-01 | D15: 110 | E15: 75 | F15: 1kV-XLPE-Arm-CU | G15: 2x2,5+T | H15: OTROS GABINETES | I15: Interconexiones tablero de contol - tablero de sincronismo 0 | J15: SEÑAL | K15: CPF1 | L15: 3 | M15: SI | N15: 6 | O15: 2 | P15: 8 | Q15: SEÑAL / INSTRUMENTO | R15: TABLERO/CCM
A16: C-GE10-TMC-01-2 | B16: TCA10-GE-10 | C16: TMC-01 | D16: 110 | E16: 75 | F16: 1kV-XLPE-Arm-CU | G16: 12x2,5 | H16: OTROS GABINETES | I16: Interconexiones tablero de contol - tablero de sincronismo 0 | J16: SEÑAL | K16: CPF1 | L16: 12 | M16: SI | N16: 24 | O16: 2 | P16: 26 | Q16: SEÑAL / INSTRUMENTO | R16: TABLERO/CCM
A17: C-GE10-TMC-01-2 | B17: TCA10-GE-10 | C17: TMC-01 | D17: 110 | E17: 75 | F17: 1kV-XLPE-Arm-CU | G17: 12x2,5 | H17: OTROS GABINETES | I17: Interconexiones tablero de contol - tablero de sincronismo 0 | J17: SEÑAL | K17: CPF1 | L17: 12 | M17: SI | N17: 24 | O17: 2 | P17: 26 | Q17: SEÑAL / INSTRUMENTO | R17: TABLERO/CCM
A18: C-GE10-TMC-01-2 | B18: TCA10-GE-10 | C18: TMC-01 | D18: 110 | E18: 75 | F18: 1kV-XLPE-Arm-CU | G18: 12x2,5 | H18: OTROS GABINETES | I18: Interconexiones tablero de contol - tablero de sincronismo 0 | J18: SEÑAL | K18: CPF1 | L18: 12 | M18: SI | N18: 24 | O18: 2 | P18: 26 | Q18: SEÑAL / INSTRUMENTO | R18: TABLERO/CCM
A19: C-GE10-TMC-01-5 | B19: TCA10-GE-10 | C19: TMC-01 | D19: 110 | E19: 75 | F19: 1kV-XLPE-Arm-CU | G19: 12x2,5 | H19: OTROS GABINETES | I19: Interconexiones tablero de contol - tablero de sincronismo 0 | J19: SEÑAL | K19: CPF1 | L19: 12 | M19: SI | N19: 24 | O19: 2 | P19: 26 | Q19: SEÑAL / INSTRUMENTO | R19: TABLERO/CCM
A20: C-GE10-TMC-01-6 | B20: TCA10-GE-10 | C20: TMC-01 | D20: 110 | E20: 75 | F20: 1kV-XLPE-Arm-CU | G20: 2x2,5+T | H20: OTROS GABINETES | J20: SEÑAL | K20: CPF1 | L20: 3 | M20: SI | N20: 6 | O20: 2 | P20: 8 | Q20: SEÑAL / INSTRUMENTO | R20: OTROS/VERIFICAR
A21: C-GE10-TMC-01-7 | B21: TCA10-GE-10 | C21: TMC-01 | D21: 110 | E21: 75 | F21: 1kV-XLPE-Arm-CU | G21: 2x2,5+T | H21: OTROS GABINETES | I21: Equilibrio de cargas 0 | J21: SEÑAL | K21: CPF1 | L21: 3 | M21: SI | N21: 6 | O21: 2 | P21: 8 | Q21: SEÑAL / INSTRUMENTO | R21: OTROS/VERIFICAR
A22: C-GE10-TMC-01-8 | B22: TCA10-GE-10 | C22: TMC-01 | D22: 110 | E22: 75 | F22: 1kV-XLPE-Arm-CU | G22: 2x2,5+T | H22: OTROS GABINETES | I22: Potencia de generador 0 | J22: SEÑAL | K22: CPF1 | L22: 3 | M22: SI | N22: 6 | O22: 2 | P22: 8 | Q22: SEÑAL / INSTRUMENTO | R22: OTROS/VERIFICAR
A23: C-GE10-TMC-01-9 | B23: TCA10-GE-10 | C23: TMC-01 | D23: 110 | E23: 75 | F23: 1kV-XLPE-Arm-CU | G23: 2x2,5+T | H23: OTROS GABINETES | I23: Consigna de potencia del generador 0 | J23: SEÑAL | K23: CPF1 | L23: 3 | M23: SI | N23: 6 | O23: 2 | P23: 8 | Q23: SEÑAL / INSTRUMENTO | R23: OTROS/VERIFICAR
A24: C-GE10-TMC-01-10 | B24: TCA10-GE-10 | C24: TMC-01 | D24: 110 | E24: 75 | F24: 1kV-XLPE-Arm-CU | G24: 2x2,5+T | H24: OTROS GABINETES | I24: Consigna de coseno fi del generador 0 | J24: SEÑAL | K24: CPF1 | L24: 3 | M24: SI | N24: 6 | O24: 2 | P24: 8 | Q24: SEÑAL / INSTRUMENTO | R24: OTROS/VERIFICAR
A25: C-GE10-TMC-01-11 | B25: TCA10-GE-10 | C25: TMC-01 | D25: 110 | E25: 75 | F25: 1kV-XLPE-Arm-CU | G25: 2x2,5+T | H25: OTROS GABINETES | I25: DCG10 0 | J25: SEÑAL | K25: CPF1 | L25: 3 | M25: SI | N25: 6 | O25: 2 | P25: 8 | Q25: SEÑAL / INSTRUMENTO | R25: OTROS/VERIFICAR
A26: C-GE11-TMC-01-1 | B26: TCA11-GE-11 | C26: TMC-01 | D26: 110 | E26: 75 | F26: 1kV-XLPE-Arm-CU | G26: 2x2,5+T | H26: OTROS GABINETES | I26: Interconexiones tablero de contol - tablero de sincronismo 0 | J26: SEÑAL | K26: CPF1 | L26: 3 | M26: SI | N26: 6 | O26: 2 | P26: 8 | Q26: SEÑAL / INSTRUMENTO | R26: TABLERO/CCM
A27: C-GE11-TMC-01-2 | B27: TCA11-GE-11 | C27: TMC-01 | D27: 110 | E27: 75 | F27: 1kV-XLPE-Arm-CU | G27: 12x2,5 | H27: OTROS GABINETES | I27: Interconexiones tablero de contol - tablero de sincronismo 0 | J27: SEÑAL | K27: CPF1 | L27: 12 | M27: SI | N27: 24 | O27: 2 | P27: 26 | Q27: SEÑAL / INSTRUMENTO | R27: TABLERO/CCM
A28: C-GE11-TMC-01-3 | B28: TCA11-GE-11 | C28: TMC-01 | D28: 110 | E28: 75 | F28: 1kV-XLPE-Arm-CU | G28: 12x2,5 | H28: OTROS GABINETES | I28: Interconexiones tablero de contol - tablero de sincronismo 0 | J28: SEÑAL | K28: CPF1 | L28: 12 | M28: SI | N28: 24 | O28: 2 | P28: 26 | Q28: SEÑAL / INSTRUMENTO | R28: TABLERO/CCM
A29: C-GE11-TMC-01-4 | B29: TCA11-GE-11 | C29: TMC-01 | D29: 110 | E29: 75 | F29: 1kV-XLPE-Arm-CU | G29: 12x2,5 | H29: OTROS GABINETES | I29: Interconexiones tablero de contol - tablero de sincronismo 0 | J29: SEÑAL | K29: CPF1 | L29: 12 | M29: SI | N29: 24 | O29: 2 | P29: 26 | Q29: SEÑAL / INSTRUMENTO | R29: TABLERO/CCM
A30: C-GE11-TMC-01-5 | B30: TCA11-GE-11 | C30: TMC-01 | D30: 110 | E30: 75 | F30: 1kV-XLPE-Arm-CU | G30: 12x2,5 | H30: OTROS GABINETES | I30: Interconexiones tablero de contol - tablero de sincronismo 0 | J30: SEÑAL | K30: CPF1 | L30: 12 | M30: SI | N30: 24 | O30: 2 | P30: 26 | Q30: SEÑAL / INSTRUMENTO | R30: TABLERO/CCM
A31: C-GE11-TMC-01-6 | B31: TCA11-GE-11 | C31: TMC-01 | D31: 110 | E31: 75 | F31: 1kV-XLPE-Arm-CU | G31: 2x2,5+T | H31: OTROS GABINETES | J31: SEÑAL | K31: CPF1 | L31: 3 | M31: SI | N31: 6 | O31: 2 | P31: 8 | Q31: SEÑAL / INSTRUMENTO | R31: OTROS/VERIFICAR
A32: C-GE11-TMC-01-7 | B32: TCA11-GE-11 | C32: TMC-01 | D32: 110 | E32: 75 | F32: 1kV-XLPE-Arm-CU | G32: 2x2,5+T | H32: OTROS GABINETES | I32: Equilibrio de cargas 0 | J32: SEÑAL | K32: CPF1 | L32: 3 | M32: SI | N32: 6 | O32: 2 | P32: 8 | Q32: SEÑAL / INSTRUMENTO | R32: OTROS/VERIFICAR
A33: C-GE11-TMC-01-8 | B33: TCA11-GE-11 | C33: TMC-01 | D33: 110 | E33: 75 | F33: 1kV-XLPE-Arm-CU | G33: 2x2,5+T | H33: OTROS GABINETES | I33: Potencia de generador 0 | J33: SEÑAL | K33: CPF1 | L33: 3 | M33: SI | N33: 6 | O33: 2 | P33: 8 | Q33: SEÑAL / INSTRUMENTO | R33: OTROS/VERIFICAR
A34: C-GE11-TMC-01-9 | B34: TCA11-GE-11 | C34: TMC-01 | D34: 110 | E34: 75 | F34: 1kV-XLPE-Arm-CU | G34: 2x2,5+T | H34: OTROS GABINETES | I34: Consigna de potencia del generador 0 | J34: SEÑAL | K34: CPF1 | L34: 3 | M34: SI | N34: 6 | O34: 2 | P34: 8 | Q34: SEÑAL / INSTRUMENTO | R34: OTROS/VERIFICAR
A35: C-GE11-TMC-01-10 | B35: TCA11-GE-11 | C35: TMC-01 | D35: 110 | E35: 75 | F35: 1kV-XLPE-Arm-CU | G35: 2x2,5+T | H35: OTROS GABINETES | I35: Consigna de coseno fi del generador | J35: SEÑAL | K35: CPF1 | L35: 3 | M35: SI | N35: 6 | O35: 2 | P35: 8 | Q35: SEÑAL / INSTRUMENTO | R35: OTROS/VERIFICAR
A36: C-GE11-TMC-01-11 | B36: TCA11-GE-11 | C36: TMC-01 | D36: 110 | E36: 75 | F36: 1kV-XLPE-Arm-CU | G36: 2x2,5+T | H36: OTROS GABINETES | I36: DCG11 0 | J36: SEÑAL | K36: CPF1 | L36: 3 | M36: SI | N36: 6 | O36: 2 | P36: 8 | Q36: SEÑAL / INSTRUMENTO | R36: OTROS/VERIFICAR
A37: C-GE10-TTLM-01 | B37: JB-G10-1 | C37: TTLM-01 | D37: 110 | E37: 75 | F37: 1kV-XLPE-Arm-CU | G37: 7x2,5 | H37: OTROS GABINETES | I37: TABLERO DE TELEMETRIA 0 | J37: CONTROL | K37: CPF1 | L37: 7 | M37: SI | N37: 14 | O37: 2 | P37: 16 | Q37: CONTROL | R37: TABLERO/CCM
A38: C-GE11-TTLM-01 | B38: JB-G11-1 | C38: TTLM-01 | D38: 110 | E38: 75 | F38: 1kV-XLPE-Arm-CU | G38: 7x2,5 | H38: OTROS GABINETES | I38: TABLERO DE TELEMETRIA 0 | J38: CONTROL | K38: CPF1 | L38: 7 | M38: SI | N38: 14 | O38: 2 | P38: 16 | Q38: CONTROL | R38: TABLERO/CCM
A39: P-670-TRE-010-R1 | B39: KBE-600J (G10\ | C39: 670-TRE-010 | D39: 380 | E39: 20 | F39: 1kV-XLPE-Arm-CU | G39: 1x240 | H39: ÁREA GENERADORES | I39: 0 | J39: POTENCIA_BT | K39: CPF1 | L39: 1 | M39: SI | N39: 2 | O39: 2 | P39: 4 | Q39: POTENCIA BT GRANDE (≥95mm²) | R39: TABLERO/CCM
A40: P-670-TRE-010-R2 | B40: KBE-600J (G10\ | C40: 670-TRE-010 | D40: 380 | E40: 20 | F40: 1kV-XLPE-Arm-CU | G40: 1x240 | H40: ÁREA GENERADORES | I40: 0 | J40: POTENCIA_BT | K40: CPF1 | L40: 1 | M40: SI | N40: 2 | O40: 2 | P40: 4 | Q40: POTENCIA BT GRANDE (≥95mm²) | R40: TABLERO/CCM
...

Sheet 2_Resumen_Formaciones
A1: FORMACION | B1: CONST | C1: TIPO | D1: CANT_CABLES | E1: METROS_TOTAL | F1: CPF1_m | G1: CPF2_m | H1: % CPF2
A2: 7x2,5+T | B2: 1kV-XLPE-Arm-T-CU | C2: CONTROL | D2: 96 | E2: 17390 | F2: 0 | G2: 17390 | H2: 100
A3: 2x4 | B3: 1kV-XLPE-Arm-CU | C3: POTENCIA_BT | D3: 105 | E3: 10905 | F3: 540 | G3: 10365 | H3: 95
A4: 2x2,5 | B4: 1kV-XLPE-Arm-CU | C4: CONTROL | D4: 39 | E4: 7270 | F4: 200 | G4: 7070 | H4: 97.2
A5: 2x6 | B5: 1kV-XLPE-Arm-CU | C5: POTENCIA_BT | D5: 15 | E5: 4480 | F5: 0 | G5: 4480 | H5: 100
A6: 3x240 | B6: 1kV-XLPE-Arm-CU | C6: POTENCIA_BT | D6: 23 | E6: 4050 | F6: 0 | G6: 4050 | H6: 100
A7: 3x120/70 | B7: 1kV-XLPE-Arm-CU | C7: POTENCIA_BT | D7: 8 | E7: 4000 | F7: 0 | G7: 4000 | H7: 100
A8: 4x4 | B8: 1kV-XLPE-CU | C8: POTENCIA_BT | D8: 20 | E8: 3860 | F8: 130 | G8: 3730 | H8: 96.6
A9: 4x10+T | B9: 1kV-XLPE-Arm-T-RF-CU | C9: POTENCIA_BT | D9: 24 | E9: 3560 | F9: 0 | G9: 3560 | H9: 100
A10: 3x35 | B10: 1kV-XLPE-Arm-CU | C10: POTENCIA_BT | D10: 16 | E10: 2960 | F10: 0 | G10: 2960 | H10: 100
A11: 3x50 | B11: 1kV-XLPE-Arm-CU | C11: POTENCIA_BT | D11: 10 | E11: 2700 | F11: 0 | G11: 2700 | H11: 100
A12: 3x6 | B12: 1kV-XLPE-Arm-CU | C12: POTENCIA_BT | D12: 11 | E12: 2350 | F12: 0 | G12: 2350 | H12: 100
A13: 3x16 | B13: 1kV-XLPE-Arm-CU | C13: POTENCIA_BT | D13: 9 | E13: 2290 | F13: 0 | G13: 2290 | H13: 100
... A33: 7x2,5 | B33: 1kV-XLPE-Arm-CU | C33: CONTROL | D33: 10 | E33: 290 | F33: 290 | G33: 0 | H33: 0
A34: 15 | C34: CONTROL | D34: 9 | E34: 216 | F34: 0 | G34: 216 | H34: 100
A35: 3x2,5 | B35: 1kV-XLPE-Arm-CU | C35: CONTROL | D35: 6 | E35: 160 | F35: 160 | G35: 0 | H35: 0
A36: 3x95/50 | B36: 1kV-XLPE-Arm-CU | C36: POTENCIA_BT | D36: 4 | E36: 160 | F36: 0 | G36: 160 | H36: 100
A37: 1x70 | B37: 13,2kV-XLPE-Arm-B-CU | C37: POTENCIA_MT | D37: 6 | E37: 120 | F37: 120 | G37: 0 | H37: 0
A38: 2x4+T | B38: 1kV-XLPE-Arm-T-CU | C38: POTENCIA_BT | D38: 1 | E38: 100 | F38: 100 | G38: 0 | H38: 0
A39: 3x150 | B39: 1kV-XLPE-RF-CU | C39: POTENCIA_BT | D39: 5 | E39: 100 | F39: 0 | G39: 100 | H39: 100
A40: 3x150/70 | B40: 1kV-XLPE-CU | C40: POTENCIA_BT | D40: 4 | E40: 80 | F40: 0 | G40: 80 | H40: 100
A41: 2x25 | B41: 1kV-XLPE-CU | C41: CONTROL | D41: 2 | E41: 80 | F41: 0 | G41: 80 | H41: 100
A42: 3x50/25 | B42: 1kV-XLPE-Arm-CU | C42: POTENCIA_BT | D42: 1 | E42: 60 | F42: 0 | G42: 60 | H42: 100
A43: 2x95 | B43: 1kV-XLPE-RF-CU | C43: CONTROL | D43: 5 | E43: 50 | F43: 0 | G43: 50 | H43: 100
A44: 3x2,5+T | B44: 1kV-XLPE-Arm-T-CU | C44: CONTROL | D44: 2 | E44: 40 | F44: 40 | G44: 0 | H44: 0
A45: 1x2x0,5 | B45: 300 V - Arm - BG | C45: SEÑAL | D45: 2 | E45: 30 | F45: 30 | G45: 0 | H45: 0
A46: 3x240/120 | B46: 1kV-XLPE-CU | C46: POTENCIA_BT | D46: 1 | E46: 20 | F46: 0 | G46: 20 | H46: 100
... A50: 2x2x0,5 | B50: 300 V - Arm - BG/BI | C50: SEÑAL | D50: 6 | E50: 0 | F50: 0 | G50: 0 | H50: 0
A51: TOTAL | D51: 633 | E51: 85881 | F51: 4650 | G51: 81231 | H51: 94.6

Sheet 3_Cargas_CPF2
A1: TAG_EQUIPO | B1: DESCRIPCION | C1: TENSION_V | D1: CCM_ALIMENTADOR | E1: FORMACION_POTENCIA | F1: LONGITUD_m | G1: AREA | H1: TIPO_CARGA
A2: 102-BB-001A | C2: 220 | D2: 102-UPS-001-A | E2: 2x120 | F2: 10 | G2: SALA ELÉCTRICA 4 | H2: INSTRUMENTO
A3: 102-BB-001B | C3: 220 | D3: 102-UPS-001-B | E3: 2x120 | F3: 10 | G3: SALA ELÉCTRICA 3 | H3: INSTRUMENTO
A4: 102-BY-001 | C4: 380 | D4: 102-CCM-006 | E4: 3x150 | F4: 20 | G4: SALA ELÉCTRICA 3 | H4: INSTRUMENTO
A5: 102-CCM-005AUX1 | B5: ALIMENTACIÓN AUXILIAR CCM-005 0 | C5: 220 | D5: 102-DP-001UPS-A | E5: 2x4 | F5: 20 | G5: SALA ELÉCTRICA 4 | H5: SSAA
A6: 102-CCM-005AUX2 | B6: ALIMENTACIÓN AUXILIAR CCM-005 0 | C6: 220 | D6: 102-DP-001UPS-B | E6: 2x4 | F6: 20 | G6: SALA ELÉCTRICA 4 | H6: SSAA
A7: 102-CCM-005AUX3 | B7: ALIMENTACIÓN AUXILIAR CCM-005 0 | C7: 220 | D7: 102-DP-001UPS-A | E7: 2x4 | F7: 20 | G7: SALA ELÉCTRICA 4 | H7: SSAA
A8: 102-CCM-005AUX4 | B8: ALIMENTACIÓN AUXILIAR CCM-005 0 | C8: 220 | D8: 102-DP-001UPS-B | E8: 2x4 | F8: 20 | G8: SALA ELÉCTRICA 4 | H8: SSAA
A9: 102-CCM-006AUX1 | B9: ALIMENTACIÓN AUXILIAR CCM-006 0 | C9: 220 | D9: 102-DP-001UPS-A | E9: 2x4 | F9: 20 | G9: SALA ELÉCTRICA 4 | H9: SSAA
A10: 102-CCM-006AUX2 | B10: ALIMENTACIÓN AUXILIAR CCM-006 0 | C10: 220 | D10: 102-DP-001UPS-B | E10: 2x4 | F10: 20 | G10: SALA ELÉCTRICA 4 | H10: SSAA
A11: 102-CCM-006AUX3 | B11: ALIMENTACIÓN AUXILIAR CCM-006 0 | C11: 220 | D11: 102-DP-001UPS-A | E11: 2x4 | F11: 20 | G11: SALA ELÉCTRICA 4 | H11: SSAA
A12: 102-CCM-006AUX4 | B12: ALIMENTACIÓN AUXILIAR CCM-006 0 | C12: 220 | D12: 102-DP-001UPS-B | E12: 2x4 | F12: 20 | G12: SALA ELÉCTRICA 4 | H12: SSAA
A13: 102-CCM-006AUX5 | B13: ALIMENTACIÓN AUXILIAR CCM-006 0 | C13: 220 | D13: 102-DP-001UPS-A | E13: 2x4 | F13: 20 | G13: SALA ELÉCTRICA 4 | H13: SSAA
A14: 102-CCM-006AUX6 | B14: ALIMENTACIÓN AUXILIAR CCM-006 0 | C14: 220 | D14: 102-DP-001UPS-B | E14: 2x4 | F14: 20 | G14: SALA ELÉCTRICA 4 | H14: SSAA
A15: 102-CCM-007AUX1 | B15: ALIMENTACIÓN AUXILIAR CCM-007 0 | C15: 220 | D15: 102-DP-001UPS-A | E15: 2x4 | F15: 20 | G15: SALA ELÉCTRICA 4 | H15: SSAA
A16: 102-CCM-007AUX2 | B16: ALIMENTACIÓN AUXILIAR CCM-007 0 | C16: 220 | D16: 102-DP-001UPS-B | E16: 2x4 | F16: 20 | G16: SALA ELÉCTRICA 4 | H16: SSAA
... A18: 102-CCM-007AUX4 | B18: ALIMENTACIÓN AUXILIAR CCM-007 0 | C18: 220 | D18: 102-DP-001UPS-B | E18: 2x4 | F18: 20 | G18: SALA ELÉCTRICA 4 | H18: SSAA
A19: 102-DP-001 | C19: 380 | D19: 102-CCM-006 | E19: 3x150/70 | F19: 20 | G19: SALA ELÉCTRICA 4 | H19: CONTROL
A20: 102-DP-001-TRA | B20: TABLERO DE DISTRIBUCIÓN TRACING 0 | C20: 380 | D20: 102-CCM-006 | E20: 3x240/120 | F20: 20 | G20: Compressor KIM HS Prelube Heater - Área 293 | H20: CONTROL
A21: 102-DP-001UPS-A | C21: 220 | D21: 102-UPS-001-A | E21: 2x95 | F21: 10 | G21: SALA ELÉCTRICA 4 | H21: SSAA
A22: 102-DP-001UPS-B | C22: 220 | D22: 102-UPS-001-B | E22: 2x95 | F22: 10 | G22: SALA ELÉCTRICA 3 | H22: SSAA
A23: 102-DP-101 | C23: 380 | D23: 102-CCM-006 | E23: 3x25/16 | F23: 60 | G23: SALA ELÉCTRICA 3 | H23: CONTROL
A24: 102-DP-101UPS-A | C24: 220 | D24: 102-DP-001UPS-A | E24: 2x10 | F24: 60 | G24: SALA ELÉCTRICA 3 | H24: SSAA
A25: 102-DP-101UPS-B | C25: 220 | D25: 102-DP-001UPS-B | E25: 2x10 | F25: 60 | G25: SALA ELÉCTRICA 3 | H25: SSAA
A26: 102-DP-471-A | C26: 220 | D26: 102-DP-001UPS-A | E26: 2x35 | F26: 80 | G26: SALA ELÉCTRICA 3 | H26: CONTROL
A27: 102-DP-471-B | C27: 220 | D27: 102-DP-001UPS-B | E27: 2x35 | F27: 80 | G27: SALA ELÉCTRICA 4 | H27: CONTROL
A28: 102-DP-472 | C28: 380 | D28: 102-CCM-006 | E28: 3x25/16 | F28: 80 | G28: SALA ELÉCTRICA 3 | H28: CONTROL
A29: 102-DP-473A | B29: Tablero Conversión 220VAC/24VCC (Alimentador A\ 0 | C29: 220 | D29: 102-DP-471 | E29: 2x16 | F29: 10 | G29: Iluminación ext. emergencia - Área KOD | H29: CONTROL
A30: 102-DP-473B | B30: Tablero Conversión 220VAC/24VCC (Alimentador B\ 0 | C30: 220 | D30: 102-DP-471 | E30: 2x16 | F30: 10 | G30: Iluminación ext. emergencia - Área KOD | H30: CONTROL
A31: 102-DP-VFD-23310 A | B31: BOMBA DE CONDENSADO 0 | C31: 6600 | D31: 102-TGMT-002 | E31: 3x25 | F31: 20 | G31: SALA ELÉCTRICA 4 | H31: VFD_MT
A32: 102-DP-VFD-23310 B | B32: BOMBA DE CONDENSADO 0 | C32: 6600 | D32: 102-TGMT-002 | E32: 3x25 | F32: 20 | G32: SALA ELÉCTRICA 4 | H32: VFD_MT
A33: 102-DP-VFD-23310 C | B33: BOMBA DE CONDENSADO 0 | C33: 6600 | D33: 102-TGMT-002 | E33: 3x25 | F33: 20 | G33: SALA ELÉCTRICA 4 | H33: VFD_MT
A34: 102-DP-VFD-24210 A | B34: BOMBA DE INYECCION DE AGUA | C34: 460 | D34: 102-TR-24210 A | E34: 3x240 | F34: 30 | G34: SALA ELÉCTRICA 3 | H34: VFD_BT
A35: 102-DP-VFD-24210 B | B35: BOMBA DE INYECCION DE AGUA 0 | C35: 460 | D35: 102-TR-24210 B | E35: 3x240 | F35: 30 | G35: SALA ELÉCTRICA 3 | H35: VFD_BT
A36: 102-DP-VFD-24210 C | B36: BOMBA DE INYECCION DE AGUA 0 | C36: 460 | D36: 102-TR-24210 C | E36: 3x240 | F36: 30 | G36: SALA ELÉCTRICA 3 | H36: VFD_BT
A37: 102-HVAC-001 | C37: 380 | D37: 102-CCM-006 | E37: 3x95/50 | F37: 20 | G37: Compressor KIM HS Prelube Heater - Área 293 | H37: INSTRUMENTO
A38: 102-HVAC-101 | C38: 380 | D38: 102-CCM-006 | E38: 3x95/50 | F38: 60 | G38: SALA ELÉCTRICA 3 | H38: INSTRUMENTO
A39: 102-JBI-001 | C39: 380 | D39: 102-LP-001 | E39: 4x10+T | F39: 150 | G39: SALA ELÉCTRICA 3 | H39: ILUMINACION
A40: 102-JBI-002 | B40: Iluminación ext. normal - Áreas Unidad Trat de Condensado 260 y Efluentes | C40: 380 | D40: 102-LP-001 | E40: 4x10+T | F40: 130 | G40: Iluminación ext. normal - Área PTA | H40: ILUMINACION
A41: 102-JBI-003 | C41: 380 | D41: 102-LP-001 | E41: 4x10+T | F41: 220 | G41: Iluminación ext. normal - Área PTA | H41: ILUMINACION
...

Sheet 4_Estimacion_Instalacion
A1: ESTIMACIÓN DE TIEMPOS DE INSTALACIÓN ELÉCTRICA - CPF-2 LA CALERA II
A2: Base: 3 cuadrillas eléctricas x 4 personas | 8 hs/día efectivas | Rendimientos campo Patagonia
A3: CATEGORIA | B3: ITEM | C3: CANTIDAD | D3: UNIDAD | E3: RENDIMIENTO | F3: DIAS_CUADRILLA | G3: CUADRILLAS | H3: DIAS_PARALELO | I3: OBSERVACION
A4: ── TENDIDO DE CABLES ──
A5: TENDIDO | B5: Cables Potencia MT (13.2/6.6kV) | C5: 2110 | D5: m | E5: 30 m/día/cuadrilla | F5: 70.3 | G5: 2 | H5: 35.1 | I5: 18 cables | Req. maniobras especiales MT
A6: TENDIDO | B6: Cables Potencia BT Grande (≥35mm²) | C6: 17470 | D6: m | E6: 50 m/día/cuadrilla | F6: 349.4 | G6: 3 | H6: 116.5 | I6: 104 cables | 3x240, 3x150, 3x95, 3x50mm²
A7: TENDIDO | B7: Cables Potencia BT Mediano (10-35mm²) | C7: 11250 | D7: m | E7: 80 m/día/cuadrilla | F7: 140.6 | G7: 3 | H7: 46.9 | I7: 71 cables | 3x16, 3x25mm²
A8: TENDIDO | B8: Cables Potencia BT Pequeño (<10mm²) | C8: 21875 | D8: m | E8: 120 m/día/cuadrilla | F8: 182.3 | G8: 3 | H8: 60.8 | I8: 127 cables | 3x4, 3x6, 4x4mm²
A9: TENDIDO | B9: Cables Control + Señales | C9: 28126 | D9: m | E9: 100 m/día/cuadrilla | F9: 281.3 | G9: 3 | H9: 93.8 | I9: 192 cables | multiconductores
A10: TENDIDO | B10: Cables Fibra Óptica | C10: 400 | D10: m | E10: 200 m/día/cuadrilla | F10: 2 | G10: 1 | H10: 2 | I10: 1 cables FO
A11: TENDIDO | B11: Cables Ethernet UTP | C11: 0 | D11: m | E11: 150 m/día/cuadrilla | F11: 0 | G11: 1 | H11: 0 | I11: 0 cables ETH
A12: ── CONEXIONADO Y TERMINACIÓN ──
A13: CONEXIONADO | B13: Terminales MT (6.6/13.2kV) | C13: 36 | D13: extremos | E13: 8 hs/extremo = 1 día | F13: 36 | G13: 2 | H13: 18 | I13: Req. técnicos especializados MT | ABB/AESA
A14: CONEXIONADO | B14: Terminales BT Grande (≥35mm²) | C14: 208 | D14: extremos | E14: 3 hs/extremo | F14: 78 | G14: 3 | H14: 26 | I14: Zapatas + precintos + termorretráctil
A15: CONEXIONADO | B15: Terminales BT Mediano/Pequeño | C15: 396 | D15: extremos | E15: 1.5 hs/extremo | F15: 74.2 | G15: 3 | H15: 24.7 | I15: Terminales preaislados
A16: CONEXIONADO | B16: Cables de Control (peinado+etiq.+prueba) | C16: 192 | D16: cables | E16: 4 hs/cable | F16: 96 | G16: 3 | H16: 32 | I16: Incluye control, señales y vibroswitches
A17: ── MONTAJE DE EQUIPOS ──
A18: MONTAJE | B18: CCMs BT (grandes >20 bahías) | C18: 3 | D18: unidades | E18: 5 días/CCM | F18: 15 | G18: 2 | H18: 7.5 | I18: CCM-005, CCM-006, CCM-007 | Llegan en ABB S3/S4
A19: MONTAJE | B19: Celdas MT (TGMT + TRMT) | C19: 6 | D19: equipos | E19: 3 días/equipo | F19: 18 | G19: 2 | H19: 9 | I19: TGMT-001, TGMT-002, TRMT-001A/B | Izaje + nivelación
A20: MONTAJE | B20: Motores MT (>90kW, 6.6kV) | C20: 6 | D20: motores | E20: 2 días/motor | F20: 12 | G20: 2 | H20: 6 | I20: M-PAY-23310 A/B/C, M-PAZ-24210 A/B/C | Izaje + alineación
A21: MONTAJE | B21: Motores BT Grande (>90kW) | C21: 19 | D21: motores | E21: 1 día/motor | F21: 19 | G21: 3 | H21: 6.3 | I21: PAY-23040, PAZ bombas transferencia
A22: MONTAJE | B22: Motores BT Mediano (22-90kW) | C22: 42 | D22: motores | E22: 0.5 días/motor | F22: 21 | G22: 3 | H22: 7 | I22: PBM-24390, PBA-24420, etc.
A23: MONTAJE | B23: Motores BT Pequeño (<22kW) | C23: 15 | D23: motores | E23: 0.25 días/motor | F23: 3.75 | G23: 3 | H23: 1.2 | I23: Auxiliares, vibroswitches, EAL-23310
A24: ── PRUEBAS Y ENERGIZACIÓN ──
A25: PRUEBAS | B25: Pruebas de Aislación (Megger) por circuito | C25: 513 | D25: cables | E25: 2 hs/cable = 0.25 días | F25: 128.2 | G25: 3 | H25: 42.7 | I25: Incluye registro y documentación ITP
A26: PRUEBAS | B26: Energización progresiva MT → BT | C26: 1 | D26: lote | E26: 10 días fijos | F26: 10 | G26: 2 | H26: 10 | I26: Con presencia ABB + AESA + Cliente | HOLD POINT
A27: PRUEBAS | B27: Precomisionado eléctrico funcional | C27: 1 | D27: lote | E27: 15 días fijos | F27: 15 | G27: 2 | H27: 15 | I27: Loop check eléctrico + ajuste relés + secuencia arranque
A28: PRUEBAS | B28: SAT PMS en sitio (HOLD POINT PIE) | C28: 1 | D28: evento | E28: 30 días (oct-dic 2027) | F28: 30 | G28: 1 | H28: 30 | I28: Ventana oct-dic 2027 per contrato | ABB+Cliente
A30: TOTAL DÍAS ESTIMADO (CON PARALELIZACIÓN) | F30: MONTAJE TABLEROS: 9 + TENDIDO: 128 + CONEXION: 50 + PRUEBAS: 76 | H30: 263 | I30: ≈ 263 días calendario con 3 cuadrillas

Sheet 5_Cronograma_Campo
A1: CRONOGRAMA INSTALACIÓN ELÉCTRICA CPF-2 LA CALERA II - MAY 2027 → ENE 2028 | Rev 3 | 13-JUN-2026
A2: # | B2: ACTIVIDAD | C2: INICIO | D2: FIN | E2: DUR_DÍAS | F2: RESPONSABLE | G2: HITO/CONSTRAINT | H2: OBSERVACION
A3: 1 | B3: Recepción y verificación materiales eléctricos (CCMs S3/S4) | C3: 07-Apr-2027 | D3: 18-Apr-2027 | E3: 12 | F3: AESA/ABB | G3: LLEGADA S4: 07-ABR-2027 | H3: Inspección visual + megger de recepción CCMs, celdas MT
A4: 2 | B4: Montaje celdas MT: TGMT-001/003 y TRMT-001A/B (Sala 4) | C4: 14-Apr-2027 | D4: 09-May-2027 | E4: 26 | F4: ABB+AESA | G4: S4 en sitio ABR-2027 | H4: Nivelación, interconexión barras, cableado de control interno
A5: 3 | B5: Montaje CCM-005/006/007 en Sala 3 | C5: 03-May-2027 | D5: 24-May-2027 | E5: 22 | F5: ABB+AESA | G5: S3 en sitio MAY-2027 | H5: Alineación, anclaje, busbars, cableado auxiliares
A6: 4 | B6: Instalación bandejas portacables principales (campo) | C6: 21-Apr-2027 | D6: 14-May-2027 | E6: 24 | F6: AESA | H6: Bandeja MC1, MC2, MC3 - trayectos principales SE3→SE4→campo
A7: 5 | B7: Tendido cables potencia MT (13.2kV/6.6kV) | C7: 10-May-2027 | D7: 07-Jun-2027 | E7: 29 | F7: AESA | H7: Alimentadores TGMT-001A/B desde 670-TGMT-001 | Req. herram. MT
A8: 6 | B8: Tendido cables potencia BT - motores y cargas grandes | C8: 17-May-2027 | D8: 04-Jul-2027 | E8: 49 | F8: AESA | H8: 3x240, 3x150 bombas inyección | Tendido pesado en canaletas
A9: 7 | B9: Tendido cables potencia BT - cargas medianas y pequeñas | C9: 07-Jun-2027 | D9: 19-Jul-2027 | E9: 43 | F9: AESA | H9: Motores BT auxiliares, iluminación, tomacorrientes, calefacción
A10: 8 | B10: Tendido cables control y señales | C10: 14-Jun-2027 | D10: 19-Jul-2027 | E10: 36 | F10: AESA | H10: Control CCMs→motores, vibroswitches, señales VFDs
A11: 9 | B11: Tendido FO y Ethernet | C11: 21-Jun-2027 | D11: 05-Jul-2027 | E11: 15 | F11: AESA/ABB | H11: Red PMS SE3-SE4, señales digitales CPF-CPC-001
A12: 10 | B12: Conexionado y terminación cables potencia MT | C12: 07-Jun-2027 | D12: 05-Jul-2027 | E12: 29 | F12: ABB+AESA | G12: TÉCNICOS MT CERTIFICADOS | H12: Terminales premoldeadas 13.2kV | Req. ABB field service
A13: 11 | B13: Conexionado y terminación cables BT (potencia) | C13: 21-Jun-2027 | D13: 26-Jul-2027 | E13: 36 | F13: AESA | H13: Zapatas, terminales preaislados, prueba continuidad
A14: 12 | B14: Conexionado cables control (peinado + etiquetado) | C14: 05-Jul-2027 | D14: 02-Aug-2027 | E14: 29 | F14: AESA | H14: Incluye señales VFD MT, vibroswitches, HOA locales
A15: 13 | B15: Pruebas de aislación (megger) circuito por circuito | C15: 19-Jul-2027 | D15: 09-Aug-2027 | E15: 22 | F15: AESA | G15: HOLD POINT - ITP ELÉCTRICO | H15: Registro conforme ITP | Mínimo 1M Ω a 1kV / 10M Ω a 5kV
A16: 14 | B16: Energización progresiva: MT → Transformadores → BT | C16: 09-Aug-2027 | D16: 24-Aug-2027 | E16: 16 | F16: ABB+AESA+Cliente | G16: RFMC: ~15-AGO-2027 | H16: Pre-requis: Megger OK | Prot. relés ajustadas | Personal Cliente
A17: 15 | B17: Pruebas funcionales precomisionado eléctrico | C17: 18-Aug-2027 | D17: 07-Sep-2027 | E17: 21 | F17: AESA+Cliente | H17: Loop check eléctrico, secuencia arranque motores, VFD tuning
A18: 16 | B18: SAT PMS en sitio - HOLD POINT per PIE/Contrato | C18: 06-Oct-2027 | D18: 07-Dec-2027 | E18: 63 | F18: ABB+Cliente | G18: HOLD POINT: OCT-DIC 2027 | H18: Factory accepted, ahora SAT campo | 30 días ventana
A19: 17 | B19: Comisionado eléctrico integrado (con proceso) | C19: 07-Sep-2027 | D19: 15-Dec-2027 | E19: 100 | F19: AESA+ABB+Cliente | G19: INICIO COMISIONADO: 16-JUL-2027 | H19: Energizado progresivo de procesos | Coordinado con Ops
A20: 18 | B20: RFSU - Ready For Start Up | C20: 31-Jan-2028 | D20: 31-Jan-2028 | E20: 1 | F20: TODOS | G20: HITO CONTRACTUAL: 31-ENE-2028 | H20: Entrega al cliente | Todos los sistemas eléctricos operativos
A22: ANÁLISIS DE COMPATIBILIDAD CON RFSU 31-ENE-2028 | Rev 1 | 09-JUN-2026
A23: Días disponibles MAY-2027 → ENE-2028 | D23: 273 días = 39 semanas (03-MAY-2027 → 31-ENE-2028) | H23: INFO
A24: Días estimados instalación (paralelizado 3 cuadrillas) | D24: ~263 días | Ruta crítica: Tendido BT Grande (17,470m / 50m/día/cuadrilla) | H24: INFO
A25: Margen disponible | D25: 10 días de margen (4%) ACEPTABLE | H25: RIESGO
A26: Ruta Crítica (CP) identificada | D26: Tendido BT Grande 3x240/3x150 (104 cables, 17,470m) → Conexionado MT → SAT PMS → Comisionado | H26: CRITICO
A27: Riesgo 1: Volumen tendido BT Grande | D27: 104 cables / 17,470m de 3x240/3x150/3x95mm² → Ruta crítica. Opción: agregar 1 cuadrilla extra en este frente | H27: CRITICO
A28: Riesgo 2: Llegada Salas Eléctricas ABB | D28: S4: ABR-2027 | S3: MAY-2027 → Solo 9 meses para instalar 81,231m de cables | H28: RIESGO
A29: Riesgo 3: Cables MT 13.2kV (3x95, 18 cables, 2,110m) | D29: Técnicos ABB field service certificados requeridos | Coordinación con 3 meses de antelación | H29: RIESGO
A30: Riesgo 4: SAT PMS - HOLD POINT Contractual | D30: Ventana OCT-DIC 2027 fija por contrato/PIE - No admite deslizamiento - Precondiciona comisionado | H30: CRITICO
A31: Riesgo 5: Lista de cables incompleta (Rev.0) | D31: Notas del revisor: faltan cables HOA, comunicación CCM↔PMS, señales hardwired DOL, M-94213B | H31: RIESGO
A32: Acción Recomendada | D32: Agregar 1 cuadrilla BT para tendido (total 4) en el bloque MAY-JUL-2027 para recuperar 30 días | H32: RIESGO
A33: CONCLUSIÓN GENERAL | D33: Cronograma AJUSTADO con RFSU 31-ENE-2028: 10 días de margen (4%). Requiere inicio 03-MAY-2027 y 3 cuadrillas ininterrumpidas sin imprevistos. | Rev 1 | 09-JUN-2026 | H33: OK

Sheet 6_Resumen_Ejecutivo
A1: RESUMEN EJECUTIVO - ANÁLISIS ELÉCTRICO CPF-2 LA CALERA II | Rev 3 | 13-JUN-2026
A2: Documento: ACAL-00102-LC-E-0001 Rev.0 | Unifilar: ACAL-00100-EE-E-0001-1 | Análisis: Junio 2026 | Rev 3 | 13-JUN-2026
A4: 1. VOLUMEN DE CABLES
A5: Total cables en listado | B5: 633 cables (120 CPF-1 + 513 CPF-2)
A6: Total metros CPF-2 | B6: 81,231 m (513 cables)
A7: Total metros CPF-1 | B7: 4,650 m (120 cables)
A8: Potencia MT (6.6/13.2kV) - CPF-2 | B8: 18 cables | 2,110 m
A9: Potencia BT (≤1kV) - CPF-2 | B9: 302 cables | 50,595 m
A10: Control + Señales - CPF-2 | B10: 192 cables | 28,126 m
A11: Fibra Óptica - CPF-2 | B11: 1 cables | 400 m
A12: Ethernet UTP - CPF-2 | B12: 0 cables | 0 m
A14: 2. CARGAS ELÉCTRICAS CPF-2
A15: Total equipos identificados CPF-2 | B15: 243 cargas eléctricas
A16: - CALEFACCION | B16: 12 unidades
A17: - CONTROL | B17: 29 unidades
A18: - ILUMINACION | B18: 28 unidades
A19: - INSTRUMENTO | B19: 52 unidades
A20: - MOTOR_BT | B20: 76 unidades
A21: - MOTOR_MT | B21: 3 unidades
A22: - SSAA | B22: 37 unidades
A23: - VFD_BT | B23: 3 unidades
A24: - VFD_MT | B24: 3 unidades
A26: 3. ESTIMACIÓN INSTALACIÓN CAMPO
A27: Cuadrillas eléctricas | B27: 3 cuadrillas x 4 personas = 12 personas en campo
A28: Tiempo total estimado (paralelizado) | B28: ~263 días calendario
A29: Período de trabajo | B29: MAY-2027 → ENE-2028 = 274 días disponibles
A30: Margen disponible | B30: 11 días (4.0% del total)
A31: Fecha inicio mínima recomendada | B31: 03-MAY-2027 (con llegada Sala 3)
A33: 4. HITOS CLAVE CPF-2
A34: Llegada Sala Eléctrica 4 (ABB) | B34: ~07-ABR-2027
A35: Llegada Sala Eléctrica 3 (ABB) | B35: ~03-MAY-2027
A36: Inicio precomisionado / montaje campo | B36: 03-MAY-2027
A37: Inicio comisionado | B37: 16-JUL-2027
A38: RFMC (Ready For Mechanical Completion) | B38: ~15-AGO-2027
A39: SAT PMS en sitio (ventana) | B39: OCT-DIC 2027
A40: RFSU (Ready For Start Up) | B40: 31-ENE-2028 [CONTRACTUAL]
A42: 5. ALERTAS Y RIESGOS CRÍTICOS
A43: CRÍTICO | B43: Cables MT 13.2kV requieren técnicos ABB certificados - Coordinar con 3 meses de antelación
A44: CRÍTICO | B44: SAT PMS es HOLD POINT contractual - Ventana OCT-DIC 2027 no puede deslizarse
A45: RIESGO | B45: Llegada tardía de salas eléctricas ABB comprime ventana de instalación a <9 meses
...

Sheet 8_Puntas_Conexion
A1: ANÁLISIS DE PUNTAS DE CONEXIÓN — CPF-2 LA CALERA II | Rev 3 | 13-JUN-2026 | Totales calculados con SUMIF sobre hoja 1_Cables_Completo col.P (TOTAL_PTAS)
A2: ★ CIERRE GARANTIZADO: cada celda de esta hoja usa SUMIF/SUMIFS sobre la columna P (TOTAL_PTAS) de la hoja 1_Cables_Completo — cualquier cambio en Sheet 1 actualiza automáticamente este resumen. | PUNTA = 1 conductor a conectar en 1 extremo del cable (incluye conductores + armadura si corresponde).
A4: A. TOTALES GENERALES (SUMIF directo sobre 1_Cables_Completo columna TOTAL_PTAS)
A5: Concepto | B5: Cables CPF-2 | C5: Puntas Conductores (PTAS_COND) | D5: Puntas Armadura (PTAS_ARM) | E5: TOTAL PUNTAS (SUMIF) | G5: Fórmula usada | J5: Verificación
A6: TOTAL CPF-2 — Puntas conductores | B6: =COUNTIF('1_Cables_Completo'!$K$2:$K$634,"CPF2") | C6: =SUMIF('1_Cables_Completo'!$K$2:$K$634,"CPF2",'1_Cables_Completo'!$N$2:$N$634) | D6: — | E6: — | G6: SUMIF(K,"CPF2",N) | J6: N_COND × 2 extremos por cable
A7: TOTAL CPF-2 — Puntas armadura (glands) | B7: =COUNTIFS('1_Cables_Completo'!$K$2:$K$634,"CPF2",'1_Cables_Completo'!$M$2:$M$634,"SI") | C7: — | D7: =SUMIF('1_Cables_Completo'!$K$2:$K$634,"CPF2",'1_Cables_Completo'!$O$2:$O$634) | E7: — | G7: SUMIF(K,"CPF2",O) | J7: 2 glands por cable armado
A8: ★ TOTAL CPF-2 — GRAN TOTAL PUNTAS | B8: =COUNTIF('1_Cables_Completo'!$K$2:$K$634,"CPF2") | C8: =SUMIF('1_Cables_Completo'!$K$2:$K$634,"CPF2",'1_Cables_Completo'!$N$2:$N$634) | D8: =SUMIF('1_Cables_Completo'!$K$2:$K$634,"CPF2",'1_Cables_Completo'!$O$2:$O$634) | E8: =SUMIF('1_Cables_Completo'!$K$2:$K$634,"CPF2",'1_Cables_Completo'!$P$2:$P$634) | G8: SUMIF(K,"CPF2",P) | J8: Valor esperado: 5,178
A10: B. PUNTAS POR TIPO DE CABLE — SUMIFS(P, K="CPF2", Q=tipo)
A11: Tipo de Cable | B11: Cables (COUNTIFS) | C11: Puntas Conductores | D11: Puntas Armadura | E11: TOTAL PUNTAS | F11: % del total | H11: Fórmula TOTAL_PTAS | J11: Nota
A12: POTENCIA MT (>1kV) | B12: =COUNTIFS('1_Cables_Completo'!$K$2:$K$634,"CPF2",'1_Cables_Completo'!$Q$2:$Q$634,"POTENCIA MT (>1kV)") | C12: =SUMIFS('1_Cables_Completo'!$N$2:$N$634,'1_Cables_Completo'!$K$2:$K$634,"CPF2",'1_Cables_Completo'!$Q$2:$Q$634,"POTENCIA MT (>1kV)") | D12: =SUMIFS('1_Cables_Completo'!$O$2:$O$634,'1_Cables_Completo'!$K$2:$K$634,"CPF2",'1_Cables_Completo'!$Q$2:$Q$634,"POTENCIA MT (>1kV)") | E12: =SUMIFS('1_Cables_Completo'!$P$2:$P$634,'1_Cables_Completo'!$K$2:$K$634,"CPF2",'1_Cables_Completo'!$Q$2:$Q$634,"POTENCIA MT (>1kV)") | F12: =IF(=SUMIF('1_Cables_Completo'!$K$2:$K$634,"CPF2",'1_Cables_Completo'!$P$2:$P$634)>0,=SUMIFS('1_Cables_Completo'!$P$2:$P$634,'1_Cables_Completo'!$K$2:$K$634,"CPF2",'1_Cables_Completo'!$Q$2:$Q$634,"POTENCIA MT (>1kV)")/=SUMIF('1_Cables_Completo'!$K$2:$K$634,"CPF2",'1_Cables_Completo'!$P$2:$P$634),0) | H12: SUMIFS(P,K,"CPF2",Q,"POTENCIA MT (>1kV)") | J12: Terminales a compresión MT — técnico certificado
A13: POTENCIA BT GRANDE (≥95mm²) | B13: =COUNTIFS('1_Cables_Completo'!$K$2:$K$634,"CPF2",'1_Cables_Completo'!$Q$2:$Q$634,"POTENCIA BT GRANDE (≥95mm²)") | C13: =SUMIFS('1_Cables_Completo'!$N$2:$N$634,'1_Cables_Completo'!$K$2:$K$634,"CPF2",'1_Cables_Completo'!$Q$2:$Q$634,"POTENCIA BT GRANDE (≥95mm²)") | D13: =SUMIFS('1_Cables_Completo'!$O$2:$O$634,'1_Cables_Completo'!$K$2:$K$634,"CPF2",'1_Cables_Completo'!$Q$2:$Q$634,"POTENCIA BT GRANDE (≥95mm²)") | E13: =SUMIFS('1_Cables_Completo'!$P$2:$P$634,'1_Cables_Completo'!$K$2:$K$634,"CPF2",'1_Cables_Completo'!$Q$2:$Q$634,"POTENCIA BT GRANDE (≥95mm²)") | F13: =IF(=SUMIF('1_Cables_Completo'!$K$2:$K$634,"CPF2",'1_Cables_Completo'!$P$2:$P$634)>0,=SUMIFS('1_Cables_Completo'!$P$2:$P$634,'1_Cables_Completo'!$K$2:$K$634,"CPF2",'1_Cables_Completo'!$Q$2:$Q$634,"POTENCIA BT GRANDE (≥95mm²)")/=SUMIF('1_Cables_Completo'!$K$2:$K$634,"CPF2",'1_Cables_Completo'!$P$2:$P$634),0) | H13: SUMIFS(P,K,"CPF2",Q,"POTENCIA BT GRANDE (≥95mm²)") | J13: Lugs a compresión BT
A14: POTENCIA BT MEDIANA (35-70mm²) | B14: =COUNTIFS('1_Cables_Completo'!$K$2:$K$634,"CPF2",'1_Cables_Completo'!$Q$2:$Q$634,"POTENCIA BT MEDIANA (35-70mm²)") | C14: =SUMIFS('1_Cables_Completo'!$N$2:$N$634,'1_Cables_Completo'!$K$2:$K$634,"CPF2",'1_Cables_Completo'!$Q$2:$Q$634,"POTENCIA BT MEDIANA (35-70mm²)") | D14: =SUMIFS('1_Cables_Completo'!$O$2:$O$634,'1_Cables_Completo'!$K$2:$K$634,"CPF2",'1_Cables_Completo'!$Q$2:$Q$634,"POTENCIA BT MEDIANA (35-70mm²)") | E14: =SUMIFS('1_Cables_Completo'!$P$2:$P$634,'1_Cables_Completo'!$K$2:$K$634,"CPF2",'1_Cables_Completo'!$Q$2:$Q$634,"POTENCIA BT MEDIANA (35-70mm²)") | F14: =IF(=SUMIF('1_Cables_Completo'!$K$2:$K$634,"CPF2",'1_Cables_Completo'!$P$2:$P$634)>0,=SUMIFS('1_Cables_Completo'!$P$2:$P$634,'1_Cables_Completo'!$K$2:$K$634,"CPF2",'1_Cables_Completo'!$Q$2:$Q$634,"POTENCIA BT MEDIANA (35-70mm²)")/=SUMIF('1_Cables_Completo'!$K$2:$K$634,"CPF2",'1_Cables_Completo'!$P$2:$P$634),0) | H14: SUMIFS(P,K,"CPF2",Q,"POTENCIA BT MEDIANA (35-70mm²)") | J14: Lugs a compresión BT
A15: POTENCIA BT PEQUEÑA (10-25mm²) | B15: =COUNTIFS('1_Cables_Completo'!$K$2:$K$634,"CPF2",'1_Cables_Completo'!$Q$2:$Q$634,"POTENCIA BT PEQUEÑA (10-25mm²)") | C15: =SUMIFS('1_Cables_Completo'!$N$2:$N$634,'1_Cables_Completo'!$K$2:$K$634,"CPF2",'1_Cables_Completo'!$Q$2:$Q$634,"POTENCIA BT PEQUEÑA (10-25mm²)") | D15: =SUMIFS('1_Cables_Completo'!$O$2:$O$634,'1_Cables_Completo'!$K$2:$K$634,"CPF2",'1_Cables_Completo'!$Q$2:$Q$634,"POTENCIA BT PEQUEÑA (10-25mm²)") | E15: =SUMIFS('1_Cables_Completo'!$P$2:$P$634,'1_Cables_Completo'!$K$2:$K$634,"CPF2",'1_Cables_Completo'!$Q$2:$Q$634,"POTENCIA BT PEQUEÑA (10-25mm²)") | F15: =IF(=SUMIF('1_Cables_Completo'!$K$2:$K$634,"CPF2",'1_Cables_Completo'!$P$2:$P$634)>0,=SUMIFS('1_Cables_Completo'!$P$2:$P$634,'1_Cables_Completo'!$K$2:$K$634,"CPF2",'1_Cables_Completo'!$Q$2:$Q$634,"POTENCIA BT PEQUEÑA (10-25mm²)")/=SUMIF('1_Cables_Completo'!$K$2:$K$634,"CPF2",'1_Cables_Completo'!$P$2:$P$634),0) | H15: SUMIFS(P,K,"CPF2",Q,"POTENCIA BT PEQUEÑA (10-25mm²)") | J15: Lugs a compresión BT
A16: POTENCIA BT MUY PEQ (<10mm²) | B16: =COUNTIFS('1_Cables_Completo'!$K$2:$K$634,"CPF2",'1_Cables_Completo'!$Q$2:$Q$634,"POTENCIA BT MUY PEQ (<10mm²)") | C16: =SUMIFS('1_Cables_Completo'!$N$2:$N$634,'1_Cables_Completo'!$K$2:$K$634,"CPF2",'1_Cables_Completo'!$Q$2:$Q$634,"POTENCIA BT MUY PEQ (<10mm²)") | D16: =SUMIFS('1_Cables_Completo'!$O$2:$O$634,'1_Cables_Completo'!$K$2:$K$634,"CPF2",'1_Cables_Completo'!$Q$2:$Q$634,"POTENCIA BT MUY PEQ (<10mm²)") | E16: =SUMIFS('1_Cables_Completo'!$P$2:$P$634,'1_Cables_Completo'!$K$2:$K$634,"CPF2",'1_Cables_Completo'!$Q$2:$Q$634,"POTENCIA BT MUY PEQ (<10mm²)") | F16: =IF(=SUMIF('1_Cables_Completo'!$K$2:$K$634,"CPF2",'1_Cables_Completo'!$P$2:$P$634)>0,=SUMIFS('1_Cables_Completo'!$P$2:$P$634,'1_Cables_Completo'!$K$2:$K$634,"CPF2",'1_Cables_Completo'!$Q$2:$Q$634,"POTENCIA BT MUY PEQ (<10mm²)")/=SUMIF('1_Cables_Completo'!$K$2:$K$634,"CPF2",'1_Cables_Completo'!$P$2:$P$634),0) | H16: SUMIFS(P,K,"CPF2",Q,"POTENCIA BT MUY PEQ (<10mm²)") | J16: Lugs a compresión BT
A17: CONTROL | B17: =COUNTIFS('1_Cables_Completo'!$K$2:$K$634,"CPF2",'1_Cables_Completo'!$Q$2:$Q$634,"CONTROL") | C17: =SUMIFS('1_Cables_Completo'!$N$2:$N$634,'1_Cables_Completo'!$K$2:$K$634,"CPF2",'1_Cables_Completo'!$Q$2:$Q$634,"CONTROL") | D17: =SUMIFS('1_Cables_Completo'!$O$2:$O$634,'1_Cables_Completo'!$K$2:$K$634,"CPF2",'1_Cables_Completo'!$Q$2:$Q$634,"CONTROL") | E17: =SUMIFS('1_Cables_Completo'!$P$2:$P$634,'1_Cables_Completo'!$K$2:$K$634,"CPF2",'1_Cables_Completo'!$Q$2:$Q$634,"CONTROL") | F17: =IF(=SUMIF('1_Cables_Completo'!$K$2:$K$634,"CPF2",'1_Cables_Completo'!$P$2:$P$634)>0,=SUMIFS('1_Cables_Completo'!$P$2:$P$634,'1_Cables_Completo'!$K$2:$K$634,"CPF2",'1_Cables_Completo'!$Q$2:$Q$634,"CONTROL")/=SUMIF('1_Cables_Completo'!$K$2:$K$634,"CPF2",'1_Cables_Completo'!$P$2:$P$634),0) | H17: SUMIFS(P,K,"CPF2",Q,"CONTROL") | J17: Ferrules de bornera
A18: SEÑAL / INSTRUMENTO | B18: =COUNTIFS('1_Cables_Completo'!$K$2:$K$634,"CPF2",'1_Cables_Completo'!$Q$2:$Q$634,"SEÑAL / INSTRUMENTO") | C18: =SUMIFS('1_Cables_Completo'!$N$2:$N$634,'1_Cables_Completo'!$K$2:$K$634,"CPF2",'1_Cables_Completo'!$Q$2:$Q$634,"SEÑAL / INSTRUMENTO") | D18: =SUMIFS('1_Cables_Completo'!$O$2:$O$634,'1_Cables_Completo'!$K$2:$K$634,"CPF2",'1_Cables_Completo'!$Q$2:$Q$634,"SEÑAL / INSTRUMENTO") | E18: =SUMIFS('1_Cables_Completo'!$P$2:$P$634,'1_Cables_Completo'!$K$2:$K$634,"CPF2",'1_Cables_Completo'!$Q$2:$Q$634,"SEÑAL / INSTRUMENTO") | F18: =IF(=SUMIF('1_Cables_Completo'!$K$2:$K$634,"CPF2",'1_Cables_Completo'!$P$2:$P$634)>0,=SUMIFS('1_Cables_Completo'!$P$2:$P$634,'1_Cables_Completo'!$K$2:$K$634,"CPF2",'1_Cables_Completo'!$Q$2:$Q$634,"SEÑAL / INSTRUMENTO")/=SUMIF('1_Cables_Completo'!$K$2:$K$634,"CPF2",'1_Cables_Completo'!$P$2:$P$634),0) | H18: SUMIFS(P,K,"CPF2",Q,"SEÑAL / INSTRUMENTO")
A19: FO / ETHERNET | B19: =COUNTIFS('1_Cables_Completo'!$K$2:$K$634,"CPF2",'1_Cables_Completo'!$Q$2:$Q$634,"FO / ETHERNET") | C19: =SUMIFS('1_Cables_Completo'!$N$2:$N$634,'1_Cables_Completo'!$K$2:$K$634,"CPF2",'1_Cables_Completo'!$Q$2:$Q$634,"FO / ETHERNET") | D19: =SUMIFS('1_Cables_Completo'!$O$2:$O$634,'1_Cables_Completo'!$K$2:$K$634,"CPF2",'1_Cables_Completo'!$Q$2:$Q$634,"FO / ETHERNET") | E19: =SUMIFS('1_Cables_Completo'!$P$2:$P$634,'1_Cables_Completo'!$K$2:$K$634,"CPF2",'1_Cables_Completo'!$Q$2:$Q$634,"FO / ETHERNET") | F19: =IF(=SUMIF('1_Cables_Completo'!$K$2:$K$634,"CPF2",'1_Cables_Completo'!$P$2:$P$634)>0,=SUMIFS('1_Cables_Completo'!$P$2:$P$634,'1_Cables_Completo'!$K$2:$K$634,"CPF2",'1_Cables_Completo'!$Q$2:$Q$634,"FO / ETHERNET")/=SUMIF('1_Cables_Completo'!$K$2:$K$634,"CPF2",'1_Cables_Completo'!$P$2:$P$634),0) | H19: SUMIFS(P,K,"CPF2",Q,"FO / ETHERNET") | J19: Conector SC/LC
A20: OTROS/VERIFICAR | B20: =COUNTIFS('1_Cables_Completo'!$K$2:$K$634,"CPF2",'1_Cables_Completo'!$Q$2:$Q$634,"OTROS/VERIFICAR") | C20: =SUMIFS('1_Cables_Completo'!$N$2:$N$634,'1_Cables_Completo'!$K$2:$K$634,"CPF2",'1_Cables_Completo'!$Q$2:$Q$634,"OTROS/VERIFICAR") | D20: =SUMIFS('1_Cables_Completo'!$O$2:$O$634,'1_Cables_Completo'!$K$2:$K$634,"CPF2",'1_Cables_Completo'!$Q$2:$Q$634,"OTROS/VERIFICAR") | E20: =SUMIFS('1_Cables_Completo'!$P$2:$P$634,'1_Cables_Completo'!$K$2:$K$634,"CPF2",'1_Cables_Completo'!$Q$2:$Q$634,"OTROS/VERIFICAR") | F20: =IF(=SUMIF('1_Cables_Completo'!$K$2:$K$634,"CPF2",'1_Cables_Completo'!$P$2:$P$634)>0,=SUMIFS('1_Cables_Completo'!$P$2:$P$634,'1_Cables_Completo'!$K$2:$K$634,"CPF2",'1_Cables_Completo'!$Q$2:$Q$634,"OTROS/VERIFICAR")/=SUMIF('1_Cables_Completo'!$K$2:$K$634,"CPF2",'1_Cables_Completo'!$P$2:$P$634),0) | H20: SUMIFS(P,K,"CPF2",Q,"OTROS/VERIFICAR")
A21: TOTAL (debe = Gran Total sección A) | B21: =COUNTIF('1_Cables_Completo'!$K$2:$K$634,"CPF2") | C21: =SUMIF('1_Cables_Completo'!$K$2:$K$634,"CPF2",'1_Cables_Completo'!$N$2:$N$634) | D21: =SUMIF('1_Cables_Completo'!$K$2:$K$634,"CPF2",'1_Cables_Completo'!$O$2:$O$634) | E21: =SUMIF('1_Cables_Completo'!$K$2:$K$634,"CPF2",'1_Cables_Completo'!$P$2:$P$634) | F21: =IF(=SUMIF('1_Cables_Completo'!$K$2:$K$634,"CPF2",'1_Cables_Completo'!$P$2:$P$634)==SUMIF('1_Cables_Completo'!$K$2:$K$634,"CPF2",'1_Cables_Completo'!$P$2:$P$634),"✓ CIERRA","✗ REVISAR")
A23: C. PUNTAS POR TIPO DE CARGA / DESTINO — SUMIFS(P, K="CPF2", R=carga)
A24: Tipo de Carga / Equipo Destino | B24: Cables | C24: Puntas Conductores | D24: Puntas Armadura | E24: TOTAL PUNTAS | F24: % del total | H24: Fórmula TOTAL_PTAS | J24: Nota
A25: MOTOR/ACCIONAMIENTO | B25: =COUNTIFS('1_Cables_Completo'!$K$2:$K$634,"CPF2",'1_Cables_Completo'!$R$2:$R$634,"MOTOR/ACCIONAMIENTO") | C25: =SUMIFS('1_Cables_Completo'!$N$2:$N$634,'1_Cables_Completo'!$K$2:$K$634,"CPF2",'1_Cables_Completo'!$R$2:$R$634,"MOTOR/ACCIONAMIENTO") | D25: =SUMIFS('1_Cables_Completo'!$O$2:$O$634,'1_Cables_Completo'!$K$2:$K$634,"CPF2",'1_Cables_Completo'!$R$2:$R$634,"MOTOR/ACCIONAMIENTO") | E25: =SUMIFS('1_Cables_Completo'!$P$2:$P$634,'1_Cables_Completo'!$K$2:$K$634,"CPF2",'1_Cables_Completo'!$R$2:$R$634,"MOTOR/ACCIONAMIENTO") | F25: =IF(=SUMIF('1_Cables_Completo'!$K$2:$K$634,"CPF2",'1_Cables_Completo'!$P$2:$P$634)>0,=SUMIFS('1_Cables_Completo'!$P$2:$P$634,'1_Cables_Completo'!$K$2:$K$634,"CPF2",'1_Cables_Completo'!$R$2:$R$634,"MOTOR/ACCIONAMIENTO")/=SUMIF('1_Cables_Completo'!$K$2:$K$634,"CPF2",'1_Cables_Completo'!$P$2:$P$634),0) | H25: SUMIFS(P,K,"CPF2",R,"MOTOR/ACCIONAMIENTO") | J25: Terminales en caja JB del motor / borne motor
A26: VFD/VARIADOR | B26: =COUNTIFS('1_Cables_Completo'!$K$2:$K$634,"CPF2",'1_Cables_Completo'!$R$2:$R$634,"VFD/VARIADOR") | C26: =SUMIFS('1_Cables_Completo'!$N$2:$N$634,'1_Cables_Completo'!$K$2:$K$634,"CPF2",'1_Cables_Completo'!$R$2:$R$634,"VFD/VARIADOR") | D26: =SUMIFS('1_Cables_Completo'!$O$2:$O$634,'1_Cables_Completo'!$K$2:$K$634,"CPF2",'1_Cables_Completo'!$R$2:$R$634,"VFD/VARIADOR") | E26: =SUMIFS('1_Cables_Completo'!$P$2:$P$634,'1_Cables_Completo'!$K$2:$K$634,"CPF2",'1_Cables_Completo'!$R$2:$R$634,"VFD/VARIADOR") | F26: =IF(=SUMIF('1_Cables_Completo'!$K$2:$K$634,"CPF2",'1_Cables_Completo'!$P$2:$P$634)>0,=SUMIFS('1_Cables_Completo'!$P$2:$P$634,'1_Cables_Completo'!$K$2:$K$634,"CPF2",'1_Cables_Completo'!$R$2:$R$634,"VFD/VARIADOR")/=SUMIF('1_Cables_Completo'!$K$2:$K$634,"CPF2",'1_Cables_Completo'!$P$2:$P$634),0) | H26: SUMIFS(P,K,"CPF2",R,"VFD/VARIADOR") | J26: Terminales en regleta de campo del VFD
A27: TABLERO/CCM | B27: =COUNTIFS('1_Cables_Completo'!$K$2:$K$634,"CPF2",'1_Cables_Completo'!$R$2:$R$634,"TABLERO/CCM") | C27: =SUMIFS('1_Cables_Completo'!$N$2:$N$634,'1_Cables_Completo'!$K$2:$K$634,"CPF2",'1_Cables_Completo'!$R$2:$R$634,"TABLERO/CCM") | D27: =SUMIFS('1_Cables_Completo'!$O$2:$O$634,'1_Cables_Completo'!$K$2:$K$634,"CPF2",'1_Cables_Completo'!$R$2:$R$634,"TABLERO/CCM") | E27: =SUMIFS('1_Cables_Completo'!$P$2:$P$634,'1_Cables_Completo'!$K$2:$K$634,"CPF2",'1_Cables_Completo'!$R$2:$R$634,"TABLERO/CCM") | F27: =IF(=SUMIF('1_Cables_Completo'!$K$2:$K$634,"CPF2",'1_Cables_Completo'!$P$2:$P$634)>0,=SUMIFS('1_Cables_Completo'!$P$2:$P$634,'1_Cables_Completo'!$K$2:$K$634,"CPF2",'1_Cables_Completo'!$R$2:$R$634,"TABLERO/CCM")/=SUMIF('1_Cables_Completo'!$K$2:$K$634,"CPF2",'1_Cables_Completo'!$P$2:$P$634),0) | H27: SUMIFS(P,K,"CPF2",R,"TABLERO/CCM") | J27: Borneras en frente del tablero destino
A28: UPS/RECTIF/SSAA | B28: =COUNTIFS('1_Cables_Completo'!$K$2:$K$634,"CPF2",'1_Cables_Completo'!$R$2:$R$634,"UPS/RECTIF/SSAA") | C28: =SUMIFS('1_Cables_Completo'!$N$2:$N$634,'1_Cables_Completo'!$K$2:$K$634,"CPF2",'1_Cables_Completo'!$R$2:$R$634,"UPS/RECTIF/SSAA") | D28: =SUMIFS('1_Cables_Completo'!$O$2:$O$634,'1_Cables_Completo'!$K$2:$K$634,"CPF2",'1_Cables_Completo'!$R$2:$R$634,"UPS/RECTIF/SSAA") | E28: =SUMIFS('1_Cables_Completo'!$P$2:$P$634,'1_Cables_Completo'!$K$2:$K$634,"CPF2",'1_Cables_Completo'!$R$2:$R$634,"UPS/RECTIF/SSAA") | F28: =IF(=SUMIF('1_Cables_Completo'!$K$2:$K$634,"CPF2",'1_Cables_Completo'!$P$2:$P$634)>0,=SUMIFS('1_Cables_Completo'!$P$2:$P$634,'1_Cables_Completo'!$K$2:$K$634,"CPF2",'1_Cables_Completo'!$R$2:$R$634,"UPS/RECTIF/SSAA")/=SUMIF('1_Cables_Completo'!$K$2:$K$634,"CPF2",'1_Cables_Completo'!$P$2:$P$634),0) | H28: SUMIFS(P,K,"CPF2",R,"UPS/RECTIF/SSAA") | J28: Borneras panel UPS/VCC/ATS
A29: ILUMINACION | B29: =COUNTIFS('1_Cables_Completo'!$K$2:$K$634,"CPF2",'1_Cables_Completo'!$R$2:$R$634,"ILUMINACION") | C29: =SUMIFS('1_Cables_Completo'!$N$2:$N$634,'1_Cables_Completo'!$K$2:$K$634,"CPF2",'1_Cables_Completo'!$R$2:$R$634,"ILUMINACION") | D29: =SUMIFS('1_Cables_Completo'!$O$2:$O$634,'1_Cables_Completo'!$K$2:$K$634,"CPF2",'1_Cables_Completo'!$R$2:$R$634,"ILUMINACION") | E29: =SUMIFS('1_Cables_Completo'!$P$2:$P$634,'1_Cables_Completo'!$K$2:$K$634,"CPF2",'1_Cables_Completo'!$R$2:$R$634,"ILUMINACION") | F29: =IF(=SUMIF('1_Cables_Completo'!$K$2:$K$634,"CPF2",'1_Cables_Completo'!$P$2:$P$634)>0,=SUMIFS('1_Cables_Completo'!$P$2:$P$634,'1_Cables_Completo'!$K$2:$K$634,"CPF2",'1_Cables_Completo'!$R$2:$R$634,"ILUMINACION")/=SUMIF('1_Cables_Completo'!$K$2:$K$634,"CPF2",'1_Cables_Completo'!$P$2:$P$634),0) | H29: SUMIFS(P,K,"CPF2",R,"ILUMINACION") | J29: Regleta en caja de conexión luminaria
A30: CALEFACCION/TRAZADO | B30: =COUNTIFS('1_Cables_Completo'!$K$2:$K$634,"CPF2",'1_Cables_Completo'!$R$2:$R$634,"CALEFACCION/TRAZADO") | C30: =SUMIFS('1_Cables_Completo'!$N$2:$N$634,'1_Cables_Completo'!$K$2:$K$634,"CPF2",'1_Cables_Completo'!$R$2:$R$634,"CALEFACCION/TRAZADO") | D30: =SUMIFS('1_Cables_Completo'!$O$2:$O$634,'1_Cables_Completo'!$K$2:$K$634,"CPF2",'1_Cables_Completo'!$R$2:$R$634,"CALEFACCION/TRAZADO") | E30: =SUMIFS('1_Cables_Completo'!$P$2:$P$634,'1_Cables_Completo'!$K$2:$K$634,"CPF2",'1_Cables_Completo'!$R$2:$R$634,"CALEFACCION/TRAZADO") | F30: =IF(=SUMIF('1_Cables_Completo'!$K$2:$K$634,"CPF2",'1_Cables_Completo'!$P$2:$P$634)>0,=SUMIFS('1_Cables_Completo'!$P$2:$P$634,'1_Cables_Completo'!$K$2:$K$634,"CPF2",'1_Cables_Completo'!$R$2:$R$634,"CALEFACCION/TRAZADO")/=SUMIF('1_Cables_Completo'!$K$2:$K$634,"CPF2",'1_Cables_Completo'!$P$2:$P$634),0) | H30: SUMIFS(P,K,"CPF2",R,"CALEFACCION/TRAZADO") | J30: Borne heater / junction box trazado
A31: TOMACORRIENTE | B31: =COUNTIFS('1_Cables_Completo'!$K$2:$K$634,"CPF2",'1_Cables_Completo'!$R$2:$R$634,"TOMACORRIENTE") | C31: =SUMIFS('1_Cables_Completo'!$N$2:$N$634,'1_Cables_Completo'!$K$2:$K$634,"CPF2",'1_Cables_Completo'!$R$2:$R$634,"TOMACORRIENTE") | D31: =SUMIFS('1_Cables_Completo'!$O$2:$O$634,'1_Cables_Completo'!$K$2:$K$634,"CPF2",'1_Cables_Completo'!$R$2:$R$634,"TOMACORRIENTE") | E31: =SUMIFS('1_Cables_Completo'!$P$2:$P$634,'1_Cables_Completo'!$K$2:$K$634,"CPF2",'1_Cables_Completo'!$R$2:$R$634,"TOMACORRIENTE") | F31: =IF(=SUMIF('1_Cables_Completo'!$K$2:$K$634,"CPF2",'1_Cables_Completo'!$P$2:$P$634)>0,=SUMIFS('1_Cables_Completo'!$P$2:$P$634,'1_Cables_Completo'!$K$2:$K$634,"CPF2",'1_Cables_Completo'!$R$2:$R$634,"TOMACORRIENTE")/=SUMIF('1_Cables_Completo'!$K$2:$K$634,"CPF2",'1_Cables_Completo'!$P$2:$P$634),0) | H31: SUMIFS(P,K,"CPF2",R,"TOMACORRIENTE") | J31: Borne regleta tomacorriente
A32: INSTRUMENTO/SENSOR | B32: =COUNTIFS('1_Cables_Completo'!$K$2:$K$634,"CPF2",'1_Cables_Completo'!$R$2:$R$634,"INSTRUMENTO/SENSOR") | C32: =SUMIFS('1_Cables_Completo'!$N$2:$N$634,'1_Cables_Completo'!$K$2:$K$634,"CPF2",'1_Cables_Completo'!$R$2:$R$634,"INSTRUMENTO/SENSOR") | D32: =SUMIFS('1_Cables_Completo'!$O$2:$O$634,'1_Cables_Completo'!$K$2:$K$634,"CPF2",'1_Cables_Completo'!$R$2:$R$634,"INSTRUMENTO/SENSOR") | E32: =SUMIFS('1_Cables_Completo'!$P$2:$P$634,'1_Cables_Completo'!$K$2:$K$634,"CPF2",'1_Cables_Completo'!$R$2:$R$634,"INSTRUMENTO/SENSOR") | F32: =IF(=SUMIF('1_Cables_Completo'!$K$2:$K$634,"CPF2",'1_Cables_Completo'!$P$2:$P$634)>0,=SUMIFS('1_Cables_Completo'!$P$2:$P$634,'1_Cables_Completo'!$K$2:$K$634,"CPF2",'1_Cables_Completo'!$R$2:$R$634,"INSTRUMENTO/SENSOR")/=SUMIF('1_Cables_Completo'!$K$2:$K$634,"CPF2",'1_Cables_Completo'!$P$2:$P$634),0) | H32: SUMIFS(P,K,"CPF2",R,"INSTRUMENTO/SENSOR") | J32: Borneras Head / JB instrumento
A33: SEÑAL/FO | B33: =COUNTIFS('1_Cables_Completo'!$K$2:$K$634,"CPF2",'1_Cables_Completo'!$R$2:$R$634,"SEÑAL/FO") | C33: =SUMIFS('1_Cables_Completo'!$N$2:$N$634,'1_Cables_Completo'!$K$2:$K$634,"CPF2",'1_Cables_Completo'!$R$2:$R$634,"SEÑAL/FO") | D33: =SUMIFS('1_Cables_Completo'!$O$2:$O$634,'1_Cables_Completo'!$K$2:$K$634,"CPF2",'1_Cables_Completo'!$R$2:$R$634,"SEÑAL/FO") | E33: =SUMIFS('1_Cables_Completo'!$P$2:$P$634,'1_Cables_Completo'!$K$2:$K$634,"CPF2",'1_Cables_Completo'!$R$2:$R$634,"SEÑAL/FO") | F33: =IF(=SUMIF('1_Cables_Completo'!$K$2:$K$634,"CPF2",'1_Cables_Completo'!$P$2:$P$634)>0,=SUMIFS('1_Cables_Completo'!$P$2:$P$634,'1_Cables_Completo'!$K$2:$K$634,"CPF2",'1_Cables_Completo'!$R$2:$R$634,"SEÑAL/FO")/=SUMIF('1_Cables_Completo'!$K$2:$K$634,"CPF2",'1_Cables_Completo'!$P$2:$P$634),0) | H33: SUMIFS(P,K,"CPF2",R,"SEÑAL/FO") | J33: Conector SC/LC fibra ó bornera señal
A34: CONTROL | B34: =COUNTIFS('1_Cables_Completo'!$K$2:$K$634,"CPF2",'1_Cables_Completo'!$R$2:$R$634,"CONTROL") | C34: =SUMIFS('1_Cables_Completo'!$N$2:$N$634,'1_Cables_Completo'!$K$2:$K$634,"CPF2",'1_Cables_Completo'!$R$2:$R$634,"CONTROL") | D34: =SUMIFS('1_Cables_Completo'!$O$2:$O$634,'1_Cables_Completo'!$K$2:$K$634,"CPF2",'1_Cables_Completo'!$R$2:$R$634,"CONTROL") | E34: =SUMIFS('1_Cables_Completo'!$P$2:$P$634,'1_Cables_Completo'!$K$2:$K$634,"CPF2",'1_Cables_Completo'!$R$2:$R$634,"CONTROL") | F34: =IF(=SUMIF('1_Cables_Completo'!$K$2:$K$634,"CPF2",'1_Cables_Completo'!$P$2:$P$634)>0,=SUMIFS('1_Cables_Completo'!$P$2:$P$634,'1_Cables_Completo'!$K$2:$K$634,"CPF2",'1_Cables_Completo'!$R$2:$R$634,"CONTROL")/=SUMIF('1_Cables_Completo'!$K$2:$K$634,"CPF2",'1_Cables_Completo'!$P$2:$P$634),0) | H34: SUMIFS(P,K,"CPF2",R,"CONTROL") | J34: Borneras gabinete control
A35: OTROS/VERIFICAR | B35: =COUNTIFS('1_Cables_Completo'!$K$2:$K$634,"CPF2",'1_Cables_Completo'!$R$2:$R$634,"OTROS/VERIFICAR") | C35: =SUMIFS('1_Cables_Completo'!$N$2:$N$634,'1_Cables_Completo'!$K$2:$K$634,"CPF2",'1_Cables_Completo'!$R$2:$R$634,"OTROS/VERIFICAR") | D35: =SUMIFS('1_Cables_Completo'!$O$2:$O$634,'1_Cables_Completo'!$K$2:$K$634,"CPF2",'1_Cables_Completo'!$R$2:$R$634,"OTROS/VERIFICAR") | E35: =SUMIFS('1_Cables_Completo'!$P$2:$P$634,'1_Cables_Completo'!$K$2:$K$634,"CPF2",'1_Cables_Completo'!$R$2:$R$634,"OTROS/VERIFICAR") | F35: =IF(=SUMIF('1_Cables_Completo'!$K$2:$K$634,"CPF2",'1_Cables_Completo'!$P$2:$P$634)>0,=SUMIFS('1_Cables_Completo'!$P$2:$P$634,'1_Cables_Completo'!$K$2:$K$634,"CPF2",'1_Cables_Completo'!$R$2:$R$634,"OTROS/VERIFICAR")/=SUMIF('1_Cables_Completo'!$K$2:$K$634,"CPF2",'1_Cables_Completo'!$P$2:$P$634),0) | H35: SUMIFS(P,K,"CPF2",R,"OTROS/VERIFICAR") | J35: Sin clasificar — revisar lista cables
A36: TOTAL (debe = Gran Total sección A) | B36: =COUNTIF('1_Cables_Completo'!$K$2:$K$634,"CPF2") | C36: =SUMIF('1_Cables_Completo'!$K$2:$K$634,"CPF2",'1_Cables_Completo'!$N$2:$N$634) | D36: =SUMIF('1_Cables_Completo'!$K$2:$K$634,"CPF2",'1_Cables_Completo'!$O$2:$O$634) | E36: =SUMIF('1_Cables_Completo'!$K$2:$K$634,"CPF2",'1_Cables_Completo'!$P$2:$P$634) | F36: =IF(=SUMIF('1_Cables_Completo'!$K$2:$K$634,"CPF2",'1_Cables_Completo'!$P$2:$P$634)==SUMIF('1_Cables_Completo'!$K$2:$K$634,"CPF2",'1_Cables_Completo'!$P$2:$P$634),"✓ CIERRA","✗ REVISAR")
A38: D. COMPARATIVO CPF-1 vs CPF-2 (CPF-1 = scope EPC externo, referencia solamente)
A39: CPF | B39: Tipo Cable | C39: Cables | D39: Puntas Conductores | E39: Puntas Armadura | F39: TOTAL PUNTAS | H39: Fórmula
A40: CPF2 | B40: POTENCIA MT (>1kV) | C40: =COUNTIFS('1_Cables_Completo'!$K$2:$K$634,"CPF2",'1_Cables_Completo'!$Q$2:$Q$634,"POTENCIA MT (>1kV)") | D40: =SUMIFS('1_Cables_Completo'!$N$2:$N$634,'1_Cables_Completo'!$K$2:$K$634,"CPF2",'1_Cables_Completo'!$Q$2:$Q$634,"POTENCIA MT (>1kV)") | E40: =SUMIFS('1_Cables_Completo'!$O$2:$O$634,'1_Cables_Completo'!$K$2:$K$634,"CPF2",'1_Cables_Completo'!$Q$2:$Q$634,"POTENCIA MT (>1kV)") | F40: =SUMIFS('1_Cables_Completo'!$P$2:$P$634,'1_Cables_Completo'!$K$2:$K$634,"CPF2",'1_Cables_Completo'!$Q$2:$Q$634,"POTENCIA MT (>1kV)")
A41: CPF2 | B41: POTENCIA BT GRANDE (≥95mm²) | C41: =COUNTIFS('1_Cables_Completo'!$K$2:$K$634,"CPF2",'1_Cables_Completo'!$Q$2:$Q$634,"POTENCIA BT GRANDE (≥95mm²)") | D41: =SUMIFS('1_Cables_Completo'!$N$2:$N$634,'1_Cables_Completo'!$K$2:$K$634,"CPF2",'1_Cables_Completo'!$Q$2:$Q$634,"POTENCIA BT GRANDE (≥95mm²)") | E41: =SUMIFS('1_Cables_Completo'!$O$2:$O$634,'1_Cables_Completo'!$K$2:$K$634,"CPF2",'1_Cables_Completo'!$Q$2:$Q$634,"POTENCIA BT GRANDE (≥95mm²)") | F41: =SUMIFS('1_Cables_Completo'!$P$2:$P$634,'1_Cables_Completo'!$K$2:$K$634,"CPF2",'1_Cables_Completo'!$Q$2:$Q$634,"POTENCIA BT GRANDE (≥95mm²)")
A42: CPF2 | B42: POTENCIA BT MEDIANA (35-70mm²) | C42: =COUNTIFS('1_Cables_Completo'!$K$2:$K$634,"CPF2",'1_Cables_Completo'!$Q$2:$Q$634,"POTENCIA BT MEDIANA (35-70mm²)") | D42: =SUMIFS('1_Cables_Completo'!$N$2:$N$634,'1_Cables_Completo'!$K$2:$K$634,"CPF2",'1_Cables_Completo'!$Q$2:$Q$634,"POTENCIA BT MEDIANA (35-70mm²)") | E42: =SUMIFS('1_Cables_Completo'!$O$2:$O$634,'1_Cables_Completo'!$K$2:$K$634,"CPF2",'1_Cables_Completo'!$Q$2:$Q$634,"POTENCIA BT MEDIANA (35-70mm²)") | F42: =SUMIFS('1_Cables_Completo'!$P$2:$P$634,'1_Cables_Completo'!$K$2:$K$634,"CPF2",'1_Cables_Completo'!$Q$2:$Q$634,"POTENCIA BT MEDIANA (35-70mm²)")
A43: CPF2 | B43: POTENCIA BT PEQUEÑA (10-25mm²) | C43: =COUNTIFS('1_Cables_Completo'!$K$2:$K$634,"CPF2",'1_Cables_Completo'!$Q$2:$Q$634,"POTENCIA BT PEQUEÑA (10-25mm²)") | D43: =SUMIFS('1_Cables_Completo'!$N$2:$N$634,'1_Cables_Completo'!$K$2:$K$634,"CPF2",'1_Cables_Completo'!$Q$2:$Q$634,"POTENCIA BT PEQUEÑA (10-25mm²)") | E43: =SUMIFS('1_Cables_Completo'!$O$2:$O$634,'1_Cables_Completo'!$K$2:$K$634,"CPF2",'1_Cables_Completo'!$Q$2:$Q$634,"POTENCIA BT PEQUEÑA (10-25mm²)") | F43: =SUMIFS('1_Cables_Completo'!$P$2:$P$634,'1_Cables_Completo'!$K$2:$K$634,"CPF2",'1_Cables_Completo'!$Q$2:$Q$634,"POTENCIA BT PEQUEÑA (10-25mm²)")
A44: CPF2 | B44: POTENCIA BT MUY PEQ (<10mm²) | C44: =COUNTIFS('1_Cables_Completo'!$K$2:$K$634,"CPF2",'1_Cables_Completo'!$Q$2:$Q$634,"POTENCIA BT MUY PEQ (<10mm²)") | D44: =SUMIFS('1_Cables_Completo'!$N$2:$N$634,'1_Cables_Completo'!$K$2:$K$634,"CPF2",'1_Cables_Completo'!$Q$2:$Q$634,"POTENCIA BT MUY PEQ (<10mm²)") | E44: =SUMIFS('1_Cables_Completo'!$O$2:$O$634,'1_Cables_Completo'!$K$2:$K$634,"CPF2",'1_Cables_Completo'!$Q$2:$Q$634,"POTENCIA BT MUY PEQ (<10mm²)") | F44: =SUMIFS('1_Cables_Completo'!$P$2:$P$634,'1_Cables_Completo'!$K$2:$K$634,"CPF2",'1_Cables_Completo'!$Q$2:$Q$634,"POTENCIA BT MUY PEQ (<10mm²)")
...

Sheet 9_Lista_Materiales
A1: LISTADO DE MATERIALES — CABLES ELÉCTRICOS | Ref. Doc: ACAL-00102-LM-E-0012-0 | Rev 3 | 13-JUN-2026 | CPF-2 LA CALERA II
A2: Documento oficial de materiales de cables para aprovisionamiento CPF-2. Las cantidades incluyen el surplus aprobado por formación. La 'FORMACIÓN' normalizada permite el cruce con la hoja 1_Cables_Completo. Revisión 0 del LM emitida el 11-JUN-2026 — sin cambios respecto a revisiones previas (Dif.=0).
A4: # | B4: Item LM | C4: Código ABB/Cliente | D4: Formación (normalizada) | E4: Descripción del Material | F4: Tensión | G4: Armado (SI/NO) | H4: Cant. Base (m) | I4: Surplus (m) | J4: Sur % | K4: TOTAL c/Surplus (m) | L4: Notas
A5: CABLES DE MEDIA TENSIÓN
A6: 1 | B6: 1.1 | C6: XLFMT_14387151 | D6: 1x70mm² MT | E6: Medium Voltage Power Cable, 1Ph Uo/U=10.5/13.2 | F6: 10.5/13.2 kV | G6: SI | H6: 120 | I6: 12 | J6: 10% | K6: 132
A7: 2 | B7: 1.2 | C7: XLFMT_14387589 | D7: 3x95mm² MT | E7: Medium Voltage Power Cable, 3Ph Uo/U=10.5/13.2 | F7: 10.5/13.2 kV | G7: SI | H7: 474 | I7: 23.7 | J7: 5% | K7: 497.7
A8: 3 | B8: 1.3 | C8: XLFMT_14387574 | D8: 3x150mm² MT | E8: Medium Voltage Power Cable, 3Ph Uo/U=10.5/13.2 | F8: 10.5/13.2 kV | G8: SI | H8: 600 | I8: 30 | J8: 5% | K8: 630
A9: 4 | B9: 1.4 | C9: XLFMT_14386605 | D9: 3x25mm² MT | E9: Medium Voltage Power Cable, 3Ph Uo/U=5.2/6.6 | F9: 5.2/6.6 kV | G9: SI | H9: 1170 | I9: 58.5 | J9: 5% | K9: 1228.5
A10: 5 | B10: 1.5 | C10: XLFMT_14386596 | D10: 3x95mm² MT | E10: Medium Voltage Power Cable, 3Ph Uo/U=5.2/6.6 | F10: 5.2/6.6 kV | G10: SI | H10: 30 | I10: 4.5 | J10: 15% | K10: 34.5
A11: Subtotal CABLES DE MEDIA TENSIÓN (5 tipos) | H11: 2394 | I11: 128.7 | J11: 5% | K11: 2522.7
A12: CABLES DE BAJA TENSIÓN SIN ARMAR
A13: 6 | B13: 2.1 | C13: XLFBT_14368315 | D13: 2x4mm² Arm | E13: Low Voltage Power Cable, 1Ph+N Uo/U= | F13: 0.6/1 kV | G13: SI | H13: 305 | I13: 30.5 | J13: 10% | K13: 335.5
