Workbook
Name \0: #REF!
Name \054: #N/A
Name \a: #REF!
Name \b: #REF!
Name \c: #REF!
Name \CARBU: #REF!
Name \DOLAR: #REF!
Name \e: #REF!
Name \f: #REF!
Name \FA: #REF!
Name \g: #REF!
Name \GSGRAL: #REF!
Name \h: #REF!
Name \HORAS: #REF!
Name \JORNAL: #REF!
Name \k: #REF!
Name \l: #REF!
Name \m: #REF!
Name \n: #REF!
Name \ñ: #REF!
Name \OBR: #REF!
Name \OWNER: #REF!
Name \p: #REF!
Name \R: #REF!
Name \REPREP: #REF!
Name \RUBROS: #REF!
Name \s: #REF!
Name \SUELDOS: #REF!
Name \t: #REF!
Name \TITULO: #REF!
Name \VIAJES: #REF!
Name \w: #REF!
Name \x: #REF!
Name \y: #REF!
Name \z: #REF!
Name _: #REF!
Name _______Rev1: #REF!
Name _______Rev2: #REF!
Name _______Rev3: #REF!
Name ______Rev1: #REF!
Name ______Rev2: #REF!
Name ______Rev3: #REF!
Name ______Rev4: #REF!
Name _____Rev1: #REF!
Name _____Rev2: #REF!
Name _____Rev3: #REF!
Name _____Rev4: #REF!
Name ____Rev1: #REF!
Name ____Rev2: #REF!
Name ____Rev3: #REF!
Name ____Rev4: #REF!
Name ___ACC53: #REF!
Name ___ACC54: #REF!
Name ___ACC56: #REF!
Name ___asp2: #REF!
Name ___BUT38: #REF!
Name ___BUT78: #REF!
Name ___F15p: #REF!
Name ___fc: #REF!
Name ___Ind1: #REF!

Sheet Preliminar
A1: SUMINISTROS PROYECTO XX | D1: TAG | E1: RI | J1: Emisión y liberación de Solped | R1: Recepción de ofertas | Y1: AT REV A | AC1: AT REV 0 | AJ1: Emisión OC | AV1: Fabricación | BC1: Transporte Internacional (incluida gestión comex+transporte) | BJ1: Nacionalización (tiempo Comex para nacionalizar) | BQ1: Transporte Local | BX1: Necesidad Construcciónes | BY1: Impacto Costrucciones | CB1: -30 | CC1: 0
CB2: 1 | CC2: 90
A3: ESP | B3: Requisición N° | C3: DESCRIPCION | D3: N° | E3: Final Prog | F3: Forecast | G3: Real | H3: Desvío | J3: Inicio Prog | K3: Final Prog | L3: Duración | M3: Forecast | N3: Real | O3: Desvío Acum | P3: N° Cesta/Solped | R3: Inicio Prog | S3: Final Prog | T3: Duración | U3: Forecast | V3: Real | W3: Desvío Acum | Y3: Final Prog | Z3: Real | AA3: Desvío Acum | AC3: Inicio Prog | AD3: Final Prog | AE3: Duración | AF3: Forecast | AG3: Real | AH3: Desvío Acum | AJ3: Inicio Prog | AK3: Final Prog | AL3: Duración | AM3: Forecast | AN3: Real | AO3: Desvío Acum | AP3: N° OC | AQ3: Pos | AR3: Proveedor | AS3: Fecha de Entrega | AT3: Lugar de entrega | AV3: Inicio Prog | AW3: Final Prog | AX3: Duración | AY3: Forecast | AZ3: Real | BA3: Desvío Acum | BC3: Inicio Prog | BD3: Final Prog | BE3: Duración | BF3: Forecast | BG3: Real | BH3: Desvío Acum | BJ3: Inicio Prog | BK3: Final Prog | BL3: Duración | BM3: Forecast | BN3: Real | BO3: Desvío Acum | BQ3: Inicio Prog | BR3: Final Prog | BS3: Duración | BT3: Forecast | BU3: Real | BV3: Desvío Acum
A4: CI-Civil | C4: RI Ignifugado | D4: - | E4: =+J4-1 -> 45389 | F4: 45371 | H4: =+F4-E4 -> -18 | J4: =+K4-L4 -> 45390 | K4: =+R4-1 -> 45397 | L4: 7 | M4: =+F4+L4 -> 45378 | O4: =+M4-K4 -> -19 | R4: =+S4-T4 -> 45398 | S4: =+AC4-1 -> 45419 | T4: 21 | U4: =+M4+T4 -> 45399 | W4: =+U4-S4 -> -20 | Y4: - | Z4: - | AA4: - | AC4: =+AD4-AE4 -> 45420 | AD4: =+AJ4-1 -> 45434 | AE4: 14 | AF4: =+IF(V4=0,U4,V4)+AE4 -> 45413 | AH4: =+AF4-AD4 -> -21 | AJ4: =+AK4-AL4 -> 45435 | AK4: =+AV4-1 -> 45449 | AL4: 14 | AM4: =+IF(AG4=0,AF4,AG4)+AL4 -> 45427 | AO4: =+AM4-AK4 -> -22 | AV4: =+AW4-AX4 -> 45450 | AW4: =+BQ4-1 -> 45540 | AX4: 90 | AY4: =+IF(AN4=0,AM4,AN4)+AX4 -> 45517 | BA4: =+AY4-AW4 -> -23 | BC4: =+BD4-BE4 -> 45541 | BD4: =+BJ4 -> 45541 | BE4: 0 | BF4: =+IF(AZ4=0,AY4,AZ4)+BE4 -> 45517 | BH4: =+BF4-BD4 -> -24 | BJ4: =+BK4-BL4 -> 45541 | BK4: =+BQ4 -> 45541 | BL4: 0 | BM4: =+IF(BG4=0,BF4,BG4)+BL4 -> 45517 | BO4: =+BM4-BK4 -> -24 | BQ4: =+BR4-BS4 -> 45541 | BR4: =+BX4 -> 45547 | BS4: 6 | BT4: =+IF(BN4=0,BM4,BN4)+BS4 -> 45523 | BV4: =+BT4-BR4 -> -24 | BX4: 45547 | BY4: =+BT4-BX4 -> -24
A5: CI-Civil | C5: RI Tinglado de compresores | E5: =+J5-1 -> 45359 | F5: 45371 | H5: =+F5-E5 -> 12 | J5: =+K5-L5 -> 45360 | K5: =+R5-1 -> 45367 | L5: 7 | M5: =+F5+L5 -> 45378 | O5: =+M5-K5 -> 11 | R5: =+S5-T5 -> 45368 | S5: =+AC5-1 -> 45389 | T5: 21 | U5: =+M5+T5 -> 45399 | W5: =+U5-S5 -> 10 | AC5: =+AD5-AE5 -> 45390 | AD5: =+AJ5-1 -> 45404 | AE5: 14 | AF5: =+IF(V5=0,U5,V5)+AE5 -> 45413 | AH5: =+AF5-AD5 -> 9 | AJ5: =+AK5-AL5 -> 45405 | AK5: =+AV5-1 -> 45419 | AL5: 14 | AM5: =+IF(AG5=0,AF5,AG5)+AL5 -> 45427 | AO5: =+AM5-AK5 -> 8 | AV5: =+AW5-AX5 -> 45420 | AW5: =+BQ5-1 -> 45540 | AX5: 120 | AY5: =+IF(AN5=0,AM5,AN5)+AX5 -> 45547 | BA5: =+AY5-AW5 -> 7 | BC5: =+BD5-BE5 -> 45541 | BD5: =+BJ5 -> 45541 | BE5: 0 | BF5: =+IF(AZ5=0,AY5,AZ5)+BE5 -> 45547 | BH5: =+BF5-BD5 -> 6 | BJ5: =+BK5-BL5 -> 45541 | BK5: =+BQ5 -> 45541 | BL5: 0 | BM5: =+IF(BG5=0,BF5,BG5)+BL5 -> 45547 | BO5: =+BM5-BK5 -> 6 | BQ5: =+BR5-BS5 -> 45541 | BR5: =+BX5 -> 45547 | BS5: 6 | BT5: =+IF(BN5=0,BM5,BN5)+BS5 -> 45553 | BV5: =+BT5-BR5 -> 6 | BX5: 45547 | BY5: =+BT5-BX5 -> 6
A6: CI-Civil | C6: RI Shelter remotas | E6: =+J6-1 -> 45329 | F6: 45371 | H6: =+F6-E6 -> 42 | J6: =+K6-L6 -> 45330 | K6: =+R6-1 -> 45337 | L6: 7 | M6: =+F6+L6 -> 45378 | O6: =+M6-K6 -> 41 | R6: =+S6-T6 -> 45338 | S6: =+AC6-1 -> 45359 | T6: 21 | U6: =+M6+T6 -> 45399 | W6: =+U6-S6 -> 40 | AC6: =+AD6-AE6 -> 45360 | AD6: =+AJ6-1 -> 45374 | AE6: 14 | AF6: =+IF(V6=0,U6,V6)+AE6 -> 45413 | AH6: =+AF6-AD6 -> 39 | AJ6: =+AK6-AL6 -> 45375 | AK6: =+AV6-1 -> 45389 | AL6: 14 | AM6: =+IF(AG6=0,AF6,AG6)+AL6 -> 45427 | AO6: =+AM6-AK6 -> 38 | AV6: =+AW6-AX6 -> 45390 | AW6: =+BQ6-1 -> 45540 | AX6: 150 | AY6: =+IF(AN6=0,AM6,AN6)+AX6 -> 45577 | BA6: =+AY6-AW6 -> 37 | BC6: =+BD6-BE6 -> 45541 | BD6: =+BJ6 -> 45541 | BE6: 0 | BF6: =+IF(AZ6=0,AY6,AZ6)+BE6 -> 45577 | BH6: =+BF6-BD6 -> 36 | BJ6: =+BK6-BL6 -> 45541 | BK6: =+BQ6 -> 45541 | BL6: 0 | BM6: =+IF(BG6=0,BF6,BG6)+BL6 -> 45577 | BO6: =+BM6-BK6 -> 36 | BQ6: =+BR6-BS6 -> 45541 | BR6: =+BX6 -> 45547 | BS6: 6 | BT6: =+IF(BN6=0,BM6,BN6)+BS6 -> 45583 | BV6: =+BT6-BR6 -> 36 | BX6: 45547 | BY6: =+BT6-BX6 -> 36
A7: CI-Civil | C7: RI Estructuras metalicas | E7: =+J7-1 -> 45359 | F7: 45371 | H7: =+F7-E7 -> 12 | J7: =+K7-L7 -> 45360 | K7: =+R7-1 -> 45367 | L7: 7 | M7: =+F7+L7 -> 45378 | O7: =+M7-K7 -> 11 | R7: =+S7-T7 -> 45368 | S7: =+AC7-1 -> 45389 | T7: 21 | U7: =+M7+T7 -> 45399 | W7: =+U7-S7 -> 10 | AC7: =+AD7-AE7 -> 45390 | AD7: =+AJ7-1 -> 45404 | AE7: 14 | AF7: =+IF(V7=0,U7,V7)+AE7 -> 45413 | AH7: =+AF7-AD7 -> 9 | AJ7: =+AK7-AL7 -> 45405 | AK7: =+AV7-1 -> 45419 | AL7: 14 | AM7: =+IF(AG7=0,AF7,AG7)+AL7 -> 45427 | AO7: =+AM7-AK7 -> 8 | AV7: =+AW7-AX7 -> 45420 | AW7: =+BQ7-1 -> 45540 | AX7: 120 | AY7: =+IF(AN7=0,AM7,AN7)+AX7 -> 45547 | BA7: =+AY7-AW7 -> 7 | BC7: =+BD7-BE7 -> 45541 | BD7: =+BJ7 -> 45541 | BE7: 0 | BF7: =+IF(AZ7=0,AY7,AZ7)+BE7 -> 45547 | BH7: =+BF7-BD7 -> 6 | BJ7: =+BK7-BL7 -> 45541 | BK7: =+BQ7 -> 45541 | BL7: 0 | BM7: =+IF(BG7=0,BF7,BG7)+BL7 -> 45547 | BO7: =+BM7-BK7 -> 6 | BQ7: =+BR7-BS7 -> 45541 | BR7: =+BX7 -> 45547 | BS7: 6 | BT7: =+IF(BN7=0,BM7,BN7)+BS7 -> 45553 | BV7: =+BT7-BR7 -> 6 | BX7: 45547 | BY7: =+BT7-BX7 -> 6
A8: CI-Civil | C8: RI Estructuras de hormigon premoldeado | E8: =+J8-1 -> 45359 | F8: 45371 | H8: =+F8-E8 -> 12 | J8: =+K8-L8 -> 45360 | K8: =+R8-1 -> 45367 | L8: 7 | M8: =+F8+L8 -> 45378 | O8: =+M8-K8 -> 11 | R8: =+S8-T8 -> 45368 | S8: =+AC8-1 -> 45389 | T8: 21 | U8: =+M8+T8 -> 45399 | W8: =+U8-S8 -> 10 | AC8: =+AD8-AE8 -> 45390 | AD8: =+AJ8-1 -> 45404 | AE8: 14 | AF8: =+IF(V8=0,U8,V8)+AE8 -> 45413 | AH8: =+AF8-AD8 -> 9 | AJ8: =+AK8-AL8 -> 45405 | AK8: =+AV8-1 -> 45419 | AL8: 14 | AM8: =+IF(AG8=0,AF8,AG8)+AL8 -> 45427 | AO8: =+AM8-AK8 -> 8 | AV8: =+AW8-AX8 -> 45420 | AW8: =+BQ8-1 -> 45540 | AX8: 120 | AY8: =+IF(AN8=0,AM8,AN8)+AX8 -> 45547 | BA8: =+AY8-AW8 -> 7 | BC8: =+BD8-BE8 -> 45541 | BD8: =+BJ8 -> 45541 | BE8: 0 | BF8: =+IF(AZ8=0,AY8,AZ8)+BE8 -> 45547 | BH8: =+BF8-BD8 -> 6 | BJ8: =+BK8-BL8 -> 45541 | BK8: =+BQ8 -> 45541 | BL8: 0 | BM8: =+IF(BG8=0,BF8,BG8)+BL8 -> 45547 | BO8: =+BM8-BK8 -> 6 | BQ8: =+BR8-BS8 -> 45541 | BR8: =+BX8 -> 45547 | BS8: 6 | BT8: =+IF(BN8=0,BM8,BN8)+BS8 -> 45553 | BV8: =+BT8-BR8 -> 6 | BX8: 45547 | BY8: =+BT8-BX8 -> 6
A9: CI-Civil | C9: RI Misceláneos (membranas, anclajes 2da etapa, etc) | E9: =+J9-1 -> 45389 | F9: 45371 | H9: =+F9-E9 -> -18 | J9: =+K9-L9 -> 45390 | K9: =+R9-1 -> 45397 | L9: 7 | M9: =+F9+L9 -> 45378 | O9: =+M9-K9 -> -19 | R9: =+S9-T9 -> 45398 | S9: =+AC9-1 -> 45419 | T9: 21 | U9: =+M9+T9 -> 45399 | W9: =+U9-S9 -> -20 | AC9: =+AD9-AE9 -> 45420 | AD9: =+AJ9-1 -> 45434 | AE9: 14 | AF9: =+IF(V9=0,U9,V9)+AE9 -> 45413 | AH9: =+AF9-AD9 -> -21 | AJ9: =+AK9-AL9 -> 45435 | AK9: =+AV9-1 -> 45449 | AL9: 14 | AM9: =+IF(AG9=0,AF9,AG9)+AL9 -> 45427 | AO9: =+AM9-AK9 -> -22 | AV9: =+AW9-AX9 -> 45450 | AW9: =+BQ9-1 -> 45540 | AX9: 90 | AY9: =+IF(AN9=0,AM9,AN9)+AX9 -> 45517 | BA9: =+AY9-AW9 -> -23 | BC9: =+BD9-BE9 -> 45541 | BD9: =+BJ9 -> 45541 | BE9: 0 | BF9: =+IF(AZ9=0,AY9,AZ9)+BE9 -> 45517 | BH9: =+BF9-BD9 -> -24 | BJ9: =+BK9-BL9 -> 45541 | BK9: =+BQ9 -> 45541 | BL9: 0 | BM9: =+IF(BG9=0,BF9,BG9)+BL9 -> 45517 | BO9: =+BM9-BK9 -> -24 | BQ9: =+BR9-BS9 -> 45541 | BR9: =+BX9 -> 45547 | BS9: 6 | BT9: =+IF(BN9=0,BM9,BN9)+BS9 -> 45523 | BV9: =+BT9-BR9 -> -24 | BX9: 45547 | BY9: =+BT9-BX9 -> -24
A10: CI-Civil | C10: RI Relevamiento topgorafico | E10: =+J10-1 -> 45329 | F10: 45350 | H10: =+F10-E10 -> 21 | J10: =+K10-L10 -> 45330 | K10: =+R10-1 -> 45337 | L10: 7 | M10: =+F10+L10 -> 45357 | O10: =+M10-K10 -> 20 | R10: =+S10-T10 -> 45338 | S10: =+AC10-1 -> 45359 | T10: 21 | U10: =+M10+T10 -> 45378 | W10: =+U10-S10 -> 19 | AC10: =+AD10-AE10 -> 45360 | AD10: =+AJ10-1 -> 45374 | AE10: 14 | AF10: =+IF(V10=0,U10,V10)+AE10 -> 45392 | AH10: =+AF10-AD10 -> 18 | AJ10: =+AK10-AL10 -> 45375 | AK10: =+AV10-1 -> 45389 | AL10: 14 | AM10: =+IF(AG10=0,AF10,AG10)+AL10 -> 45406 | AO10: =+AM10-AK10 -> 17 | AV10: =+AW10-AX10 -> 45390 | AW10: =+BQ10-1 -> 45435 | AX10: 45 | AY10: =+IF(AN10=0,AM10,AN10)+AX10 -> 45451 | BA10: =+AY10-AW10 -> 16 | BC10: =+BD10-BE10 -> 45436 | BD10: =+BJ10 -> 45436 | BE10: 0 | BF10: =+IF(AZ10=0,AY10,AZ10)+BE10 -> 45451 | BH10: =+BF10-BD10 -> 15 | BJ10: =+BK10-BL10 -> 45436 | BK10: =+BQ10 -> 45436 | BL10: 0 | BM10: =+IF(BG10=0,BF10,BG10)+BL10 -> 45451 | BO10: =+BM10-BK10 -> 15 | BQ10: =+BR10-BS10 -> 45436 | BR10: =+BX10 -> 45442 | BS10: 6 | BT10: =+IF(BN10=0,BM10,BN10)+BS10 -> 45457 | BV10: =+BT10-BR10 -> 15 | BX10: 45442 | BY10: =+BT10-BX10 -> 15
A11: CI-Civil | C11: RI Detección de Interferencias enterradas (georadar) | E11: =+J11-1 -> 45329 | F11: 45350 | H11: =+F11-E11 -> 21 | J11: =+K11-L11 -> 45330 | K11: =+R11-1 -> 45337 | L11: 7 | M11: =+F11+L11 -> 45357 | O11: =+M11-K11 -> 20 | R11: =+S11-T11 -> 45338 | S11: =+AC11-1 -> 45359 | T11: 21 | U11: =+M11+T11 -> 45378 | W11: =+U11-S11 -> 19 | AC11: =+AD11-AE11 -> 45360 | AD11: =+AJ11-1 -> 45374 | AE11: 14 | AF11: =+IF(V11=0,U11,V11)+AE11 -> 45392 | AH11: =+AF11-AD11 -> 18 | AJ11: =+AK11-AL11 -> 45375 | AK11: =+AV11-1 -> 45389 | AL11: 14 | AM11: =+IF(AG11=0,AF11,AG11)+AL11 -> 45406 | AO11: =+AM11-AK11 -> 17 | AV11: =+AW11-AX11 -> 45390 | AW11: =+BQ11-1 -> 45435 | AX11: 45 | AY11: =+IF(AN11=0,AM11,AN11)+AX11 -> 45451 | BA11: =+AY11-AW11 -> 16 | BC11: =+BD11-BE11 -> 45436 | BD11: =+BJ11 -> 45436 | BE11: 0 | BF11: =+IF(AZ11=0,AY11,AZ11)+BE11 -> 45451 | BH11: =+BF11-BD11 -> 15 | BJ11: =+BK11-BL11 -> 45436 | BK11: =+BQ11 -> 45436 | BL11: 0 | BM11: =+IF(BG11=0,BF11,BG11)+BL11 -> 45451 | BO11: =+BM11-BK11 -> 15 | BQ11: =+BR11-BS11 -> 45436 | BR11: =+BX11 -> 45442 | BS11: 6 | BT11: =+IF(BN11=0,BM11,BN11)+BS11 -> 45457 | BV11: =+BT11-BR11 -> 15 | BX11: 45442 | BY11: =+BT11-BX11 -> 15
A12: IN-Instrumentación y Control | C12: Requisición de Ingeniería Transmisor de Presión | E12: =+J12-1 -> 45407 | F12: 45397 | H12: =+F12-E12 -> -10 | J12: =+K12-L12 -> 45408 | K12: =+R12-1 -> 45415 | L12: 7 | M12: =+F12+L12 -> 45404 | O12: =+M12-K12 -> -11 | R12: =+S12-T12 -> 45416 | S12: =+AC12-1 -> 45437 | T12: 21 | U12: =+M12+T12 -> 45425 | W12: =+U12-S12 -> -12 | AC12: =+AD12-AE12 -> 45438 | AD12: =+AJ12-1 -> 45468 | AE12: 30 | AF12: =+IF(V12=0,U12,V12)+AE12 -> 45455 | AH12: =+AF12-AD12 -> -13 | AJ12: =+AK12-AL12 -> 45469 | AK12: =+AV12-1 -> 45483 | AL12: 14 | AM12: =+IF(AG12=0,AF12,AG12)+AL12 -> 45469 | AO12: =+AM12-AK12 -> -14 | AV12: =+AW12-AX12 -> 45484 | AW12: =+BQ12-1 -> 45634 | AX12: 150 | AY12: =+IF(AN12=0,AM12,AN12)+AX12 -> 45619 | BA12: =+AY12-AW12 -> -15 | BC12: =+BD12-BE12 -> 45635 | BD12: =+BJ12 -> 45635 | BE12: 0 | BF12: =+IF(AZ12=0,AY12,AZ12)+BE12 -> 45619 | BH12: =+BF12-BD12 -> -16 | BJ12: =+BK12-BL12 -> 45635 | BK12: =+BQ12 -> 45635 | BL12: 0 | BM12: =+IF(BG12=0,BF12,BG12)+BL12 -> 45619 | BO12: =+BM12-BK12 -> -16 | BQ12: =+BR12-BS12 -> 45635 | BR12: =+BX12 -> 45641 | BS12: 6 | BT12: =+IF(BN12=0,BM12,BN12)+BS12 -> 45625 | BV12: =+BT12-BR12 -> -16 | BX12: 45641 | BY12: =+BT12-BX12 -> -16
A13: IN-Instrumentación y Control | C13: Requisición de Ingeniería Transmisor de Presión Diferencial | E13: =+J13-1 -> 45407 | F13: 45397 | H13: =+F13-E13 -> -10 | J13: =+K13-L13 -> 45408 | K13: =+R13-1 -> 45415 | L13: 7 | M13: =+F13+L13 -> 45404 | O13: =+M13-K13 -> -11 | R13: =+S13-T13 -> 45416 | S13: =+AC13-1 -> 45437 | T13: 21 | U13: =+M13+T13 -> 45425 | W13: =+U13-S13 -> -12 | AC13: =+AD13-AE13 -> 45438 | AD13: =+AJ13-1 -> 45468 | AE13: 30 | AF13: =+IF(V13=0,U13,V13)+AE13 -> 45455 | AH13: =+AF13-AD13 -> -13 | AJ13: =+AK13-AL13 -> 45469 | AK13: =+AV13-1 -> 45483 | AL13: 14 | AM13: =+IF(AG13=0,AF13,AG13)+AL13 -> 45469 | AO13: =+AM13-AK13 -> -14 | AV13: =+AW13-AX13 -> 45484 | AW13: =+BQ13-1 -> 45634 | AX13: 150 | AY13: =+IF(AN13=0,AM13,AN13)+AX13 -> 45619 | BA13: =+AY13-AW13 -> -15 | BC13: =+BD13-BE13 -> 45635 | BD13: =+BJ13 -> 45635 | BE13: 0 | BF13: =+IF(AZ13=0,AY13,AZ13)+BE13 -> 45619 | BH13: =+BF13-BD13 -> -16 | BJ13: =+BK13-BL13 -> 45635 | BK13: =+BQ13 -> 45635 | BL13: 0 | BM13: =+IF(BG13=0,BF13,BG13)+BL13 -> 45619 | BO13: =+BM13-BK13 -> -16 | BQ13: =+BR13-BS13 -> 45635 | BR13: =+BX13 -> 45641 | BS13: 6 | BT13: =+IF(BN13=0,BM13,BN13)+BS13 -> 45625 | BV13: =+BT13-BR13 -> -16 | BX13: 45641 | BY13: =+BT13-BX13 -> -16
A14: IN-Instrumentación y Control | C14: Requisición de Ingeniería Transmisor de Caudal Multivariable | E14: =+J14-1 -> 45377 | F14: 45397 | H14: =+F14-E14 -> 20 | J14: =+K14-L14 -> 45378 | K14: =+R14-1 -> 45385 | L14: 7 | M14: =+F14+L14 -> 45404 | O14: =+M14-K14 -> 19 | R14: =+S14-T14 -> 45386 | S14: =+AC14-1 -> 45407 | T14: 21 | U14: =+M14+T14 -> 45425 | W14: =+U14-S14 -> 18 | AC14: =+AD14-AE14 -> 45408 | AD14: =+AJ14-1 -> 45438 | AE14: 30 | AF14: =+IF(V14=0,U14,V14)+AE14 -> 45455 | AH14: =+AF14-AD14 -> 17 | AJ14: =+AK14-AL14 -> 45439 | AK14: =+AV14-1 -> 45453 | AL14: 14 | AM14: =+IF(AG14=0,AF14,AG14)+AL14 -> 45469 | AO14: =+AM14-AK14 -> 16 | AV14: =+AW14-AX14 -> 45454 | AW14: =+BQ14-1 -> 45634 | AX14: 180 | AY14: =+IF(AN14=0,AM14,AN14)+AX14 -> 45649 | BA14: =+AY14-AW14 -> 15 | BC14: =+BD14-BE14 -> 45635 | BD14: =+BJ14 -> 45635 | BE14: 0 | BF14: =+IF(AZ14=0,AY14,AZ14)+BE14 -> 45649 | BH14: =+BF14-BD14 -> 14 | BJ14: =+BK14-BL14 -> 45635 | BK14: =+BQ14 -> 45635 | BL14: 0 | BM14: =+IF(BG14=0,BF14,BG14)+BL14 -> 45649 | BO14: =+BM14-BK14 -> 14 | BQ14: =+BR14-BS14 -> 45635 | BR14: =+BX14 -> 45641 | BS14: 6 | BT14: =+IF(BN14=0,BM14,BN14)+BS14 -> 45655 | BV14: =+BT14-BR14 -> 14 | BX14: 45641 | BY14: =+BT14-BX14 -> 14
A15: IN-Instrumentación y Control | C15: Requisición de Ingeniería Transmisor de Caudal Coriolis | E15: =+J15-1 -> 45377 | F15: 45397 | H15: =+F15-E15 -> 20 | J15: =+K15-L15 -> 45378 | K15: =+R15-1 -> 45385 | L15: 7 | M15: =+F15+L15 -> 45404 | O15: =+M15-K15 -> 19 | R15: =+S15-T15 -> 45386 | S15: =+AC15-1 -> 45407 | T15: 21 | U15: =+M15+T15 -> 45425 | W15: =+U15-S15 -> 18 | AC15: =+AD15-AE15 -> 45408 | AD15: =+AJ15-1 -> 45438 | AE15: 30 | AF15: =+IF(V15=0,U15,V15)+AE15 -> 45455 | AH15: =+AF15-AD15 -> 17 | AJ15: =+AK15-AL15 -> 45439 | AK15: =+AV15-1 -> 45453 | AL15: 14 | AM15: =+IF(AG15=0,AF15,AG15)+AL15 -> 45469 | AO15: =+AM15-AK15 -> 16 | AV15: =+AW15-AX15 -> 45454 | AW15: =+BQ15-1 -> 45634 | AX15: 180 | AY15: =+IF(AN15=0,AM15,AN15)+AX15 -> 45649 | BA15: =+AY15-AW15 -> 15 | BC15: =+BD15-BE15 -> 45635 | BD15: =+BJ15 -> 45635 | BE15: 0 | BF15: =+IF(AZ15=0,AY15,AZ15)+BE15 -> 45649 | BH15: =+BF15-BD15 -> 14 | BJ15: =+BK15-BL15 -> 45635 | BK15: =+BQ15 -> 45635 | BL15: 0 | BM15: =+IF(BG15=0,BF15,BG15)+BL15 -> 45649 | BO15: =+BM15-BK15 -> 14 | BQ15: =+BR15-BS15 -> 45635 | BR15: =+BX15 -> 45641 | BS15: 6 | BT15: =+IF(BN15=0,BM15,BN15)+BS15 -> 45655 | BV15: =+BT15-BR15 -> 14 | BX15: 45641 | BY15: =+BT15-BX15 -> 14
A16: IN-Instrumentación y Control | C16: Requisición de Ingeniería Transmisor de Caudal Presión Diferencial | E16: =+J16-1 -> 45377 | F16: 45397 | H16: =+F16-E16 -> 20 | J16: =+K16-L16 -> 45378 | K16: =+R16-1 -> 45385 | L16: 7 | M16: =+F16+L16 -> 45404 | O16: =+M16-K16 -> 19 | R16: =+S16-T16 -> 45386 | S16: =+AC16-1 -> 45407 | T16: 21 | U16: =+M16+T16 -> 45425 | W16: =+U16-S16 -> 18 | AC16: =+AD16-AE16 -> 45408 | AD16: =+AJ16-1 -> 45438 | AE16: 30 | AF16: =+IF(V16=0,U16,V16)+AE16 -> 45455 | AH16: =+AF16-AD16 -> 17 | AJ16: =+AK16-AL16 -> 45439 | AK16: =+AV16-1 -> 45453 | AL16: 14 | AM16: =+IF(AG16=0,AF16,AG16)+AL16 -> 45469 | AO16: =+AM16-AK16 -> 16 | AV16: =+AW16-AX16 -> 45454 | AW16: =+BQ16-1 -> 45634 | AX16: 180 | AY16: =+IF(AN16=0,AM16,AN16)+AX16 -> 45649 | BA16: =+AY16-AW16 -> 15 | BC16: =+BD16-BE16 -> 45635 | BD16: =+BJ16 -> 45635 | BE16: 0 | BF16: =+IF(AZ16=0,AY16,AZ16)+BE16 -> 45649 | BH16: =+BF16-BD16 -> 14 | BJ16: =+BK16-BL16 -> 45635 | BK16: =+BQ16 -> 45635 | BL16: 0 | BM16: =+IF(BG16=0,BF16,BG16)+BL16 -> 45649 | BO16: =+BM16-BK16 -> 14 | BQ16: =+BR16-BS16 -> 45635 | BR16: =+BX16 -> 45641 | BS16: 6 | BT16: =+IF(BN16=0,BM16,BN16)+BS16 -> 45655 | BV16: =+BT16-BR16 -> 14 | BX16: 45641 | BY16: =+BT16-BX16 -> 14
... A71: EL-Electricidad | C71: Materiales Misceláneos | E71: =+J71-1 -> 45435 | F71: 45397 | H71: =+F71-E71 -> -38 | J71: =+K71-L71 -> 45436 | K71: =+R71-1 -> 45443 | L71: 7 | M71: =+F71+L71 -> 45404 | O71: =+M71-K71 -> -39 | R71: =+S71-T71 -> 45444 | S71: =+AC71-1 -> 45465 | T71: 21 | U71: =+M71+T71 -> 45425 | W71: =+U71-S71 -> -40 | AC71: =+AD71-AE71 -> 45466 | AD71: =+AJ71-1 -> 45480 | AE71: 14 | AF71: =+IF(V71=0,U71,V71)+AE71 -> 45439 | AH71: =+AF71-AD71 -> -41 | AJ71: =+AK71-AL71 -> 45481 | AK71: =+AV71-1 -> 45495 | AL71: 14 | AM71: =+IF(AG71=0,AF71,AG71)+AL71 -> 45453 | AO71: =+AM71-AK71 -> -42 | AV71: =+AW71-AX71 -> 45496 | AW71: =+BQ71-1 -> 45586 | AX71: 90 | AY71: =+IF(AN71=0,AM71,AN71)+AX71 -> 45543 | BA71: =+AY71-AW71 -> -43 | BC71: =+BD71-BE71 -> 45587 | BD71: =+BJ71 -> 45587 | BE71: 0 | BF71: =+IF(AZ71=0,AY71,AZ71)+BE71 -> 45543 | BH71: =+BF71-BD71 -> -44 | BJ71: =+BK71-BL71 -> 45587 | BK71: =+BQ71 -> 45587 | BL71: 0 | BM71: =+IF(BG71=0,BF71,BG71)+BL71 -> 45543 | BO71: =+BM71-BK71 -> -44 | BQ71: =+BR71-BS71 -> 45587 | BR71: =+BX71 -> 45593 | BS71: 6 | BT71: =+IF(BN71=0,BM71,BN71)+BS71 -> 45549 | BV71: =+BT71-BR71 -> -44 | BX71: 45593 | BY71: =+BT71-BX71 -> -44
E73: LAS PLANIFICADAS P/ COMPRA EN FUNCIÓN DE ESTRATEGIA SUMINISTROS/PROYECTO | Y73: VA A DEPENDER DE CADA ESTRATEGIA DE PROYECTO | AV73: SE PUEDE ABRIR LOS TIEMPOS DE VENDORS/INSPECCIÓN, ETC | BC73: DEPENDE DE LA ESTRATEGIA DEL SUMINISTRO/PROYECTO | BQ73: SI HAY DESAGREACIÓN EN CANNING SE PUEDE PLANIFICAR TAMBIÉN | BX73: INTERNO SUMINISTROS PARA PREVEER IMPACTOS, ALERTAR Y ARTICULAR CON CONSTRUCCIONES
E77: TIEMPO PLANIFICADO DE INGENERIA | J77: TIEMPO PLANIFICADO PARA ADMINISTRACIÓN DE MATERIALES | R77: TIEMPO PLANIFICADO PARA COMPRAS | Y77: TIEMPO PLANIFICADO INGENIERÍA | AJ77: TIEMPO PLANIFICADO COMPRAS | AV77: TIEMPO PLANIFICADO INGENIERÍA/ACTIVACIÓN/INSPECCIÓN | BC77: TIEMPO PLANIFICADO COMEX | BJ77: TIEMPO PLANIFICADO COMEX | BQ77: TIEMPO PLANIFICADO LOGISTICA Y ALMACES

Sheet La Calera II - crono 4.11
A1: SUMINISTROS PROYECTO XX | D1: TAG | E1: RI | J1: Emisión y liberación de Solped | R1: Recepción de ofertas | Y1: AT REV A | AC1: AT REV 0 | AJ1: Emisión OC | AV1: Fabricación | BC1: Transporte Internacional (incluida gestión comex+transporte) | BJ1: Nacionalización (tiempo Comex para nacionalizar) | BQ1: Transporte Local | BX1: Necesidad Construcciónes | BY1: Impacto Costrucciones | CB1: -30 | CC1: 0
CB2: 1 | CC2: 90
A3: ESP | B3: Requisición N° | C3: DESCRIPCION | D3: N° | E3: Final Prog | F3: Forecast | G3: Real | H3: Desvío | J3: Inicio Prog | K3: Final Prog | L3: Duración | M3: Forecast | N3: Real | O3: Desvío Acum | P3: N° Cesta/Solped | R3: Inicio Prog | S3: Final Prog | T3: Duración | U3: Forecast | V3: Real | W3: Desvío Acum | Y3: Final Prog | Z3: Real | AA3: Desvío Acum | AC3: Inicio Prog | AD3: Final Prog | AE3: Duración | AF3: Forecast | AG3: Real | AH3: Desvío Acum | AJ3: Inicio Prog | AK3: Final Prog | AL3: Duración | AM3: Forecast | AN3: Real | AO3: Desvío Acum | AP3: N° OC | AQ3: Pos | AR3: Proveedor | AS3: Fecha de Entrega | AT3: Lugar de entrega | AV3: Inicio Prog | AW3: Final Prog | AX3: Duración | AY3: Forecast | AZ3: Real | BA3: Desvío Acum | BC3: Inicio Prog | BD3: Final Prog | BE3: Duración | BF3: Forecast | BG3: Real | BH3: Desvío Acum | BJ3: Inicio Prog | BK3: Final Prog | BL3: Duración | BM3: Forecast | BN3: Real | BO3: Desvío Acum | BQ3: Inicio Prog | BR3: Final Prog | BS3: Duración | BT3: Forecast | BU3: Real | BV3: Desvío Acum
A4: EM-Mecánica | C4: Calentador eléctrico | D4: - | E4: =+J4-1 -> 45744 | H4: =+F4-E4 -> -45744 | J4: =+K4-L4 -> 45745 | K4: =+R4-1 -> 45752 | L4: 7 | M4: =+F4+L4 -> 7 | O4: =+M4-K4 -> -45745 | R4: =+S4-T4 -> 45753 | S4: =+AC4-1 -> 45783 | T4: 30 | U4: =+M4+T4 -> 37 | W4: =+U4-S4 -> -45746 | Y4: - | Z4: - | AA4: - | AC4: =+AD4-AE4 -> 45784 | AD4: =+AJ4-1 -> 45829 | AE4: 45 | AF4: =+IF(V4=0,U4,V4)+AE4 -> 82 | AH4: =+AF4-AD4 -> -45747 | AJ4: =+AK4-AL4 -> 45830 | AK4: =+AV4-1 -> 45844 | AL4: 14 | AM4: =+IF(AG4=0,AF4,AG4)+AL4 -> 96 | AO4: =+AM4-AK4 -> -45748 | AV4: =+AW4-AX4 -> 45845 | AW4: =+BQ4-1 -> 46145 | AX4: 300 | AY4: =+IF(AN4=0,AM4,AN4)+AX4 -> 396 | BA4: =+AY4-AW4 -> -45749 | BC4: =+BD4-BE4 -> 46146 | BD4: =+BJ4 -> 46146 | BE4: 0 | BF4: =+IF(AZ4=0,AY4,AZ4)+BE4 -> 396 | BH4: =+BF4-BD4 -> -45750 | BJ4: =+BK4-BL4 -> 46146 | BK4: =+BQ4 -> 46146 | BL4: 0 | BM4: =+IF(BG4=0,BF4,BG4)+BL4 -> 396 | BO4: =+BM4-BK4 -> -45750 | BQ4: =+BR4-BS4 -> 46146 | BR4: =+BX4 -> 46153 | BS4: 7 | BT4: =+IF(BN4=0,BM4,BN4)+BS4 -> 403 | BV4: =+BT4-BR4 -> -45750 | BX4: 46153 | BY4: =+BT4-BX4 -> -45750 | CA4: Fecha de equipos estáticos y paquetes crono 4/11/24
A5: EM-Mecánica | C5: Intercambiador gas-gas | E5: =+J5-1 -> 45774 | H5: =+F5-E5 -> -45774 | J5: =+K5-L5 -> 45775 | K5: =+R5-1 -> 45782 | L5: 7 | M5: =+F5+L5 -> 7 | O5: =+M5-K5 -> -45775 | R5: =+S5-T5 -> 45783 | S5: =+AC5-1 -> 45813 | T5: 30 | U5: =+M5+T5 -> 37 | W5: =+U5-S5 -> -45776 | AC5: =+AD5-AE5 -> 45814 | AD5: =+AJ5-1 -> 45859 | AE5: 45 | AF5: =+IF(V5=0,U5,V5)+AE5 -> 82 | AH5: =+AF5-AD5 -> -45777 | AJ5: =+AK5-AL5 -> 45860 | AK5: =+AV5-1 -> 45874 | AL5: 14 | AM5: =+IF(AG5=0,AF5,AG5)+AL5 -> 96 | AO5: =+AM5-AK5 -> -45778 | AV5: =+AW5-AX5 -> 45875 | AW5: =+BQ5-1 -> 46145 | AX5: 270 | AY5: =+IF(AN5=0,AM5,AN5)+AX5 -> 366 | BA5: =+AY5-AW5 -> -45779 | BC5: =+BD5-BE5 -> 46146 | BD5: =+BJ5 -> 46146 | BE5: 0 | BF5: =+IF(AZ5=0,AY5,AZ5)+BE5 -> 366 | BH5: =+BF5-BD5 -> -45780 | BJ5: =+BK5-BL5 -> 46146 | BK5: =+BQ5 -> 46146 | BL5: 0 | BM5: =+IF(BG5=0,BF5,BG5)+BL5 -> 366 | BO5: =+BM5-BK5 -> -45780 | BQ5: =+BR5-BS5 -> 46146 | BR5: =+BX5 -> 46153 | BS5: 7 | BT5: =+IF(BN5=0,BM5,BN5)+BS5 -> 373 | BV5: =+BT5-BR5 -> -45780 | BX5: 46153 | BY5: =+BT5-BX5 -> -45780 | CA5: Fecha de equipos estáticos y paquetes crono 4/11/24
A6: EM-Mecánica | C6: Separador de gas combustible | E6: =+J6-1 -> 45744 | H6: =+F6-E6 -> -45744 | J6: =+K6-L6 -> 45745 | K6: =+R6-1 -> 45752 | L6: 7 | M6: =+F6+L6 -> 7 | O6: =+M6-K6 -> -45745 | R6: =+S6-T6 -> 45753 | S6: =+AC6-1 -> 45783 | T6: 30 | U6: =+M6+T6 -> 37 | W6: =+U6-S6 -> -45746 | AC6: =+AD6-AE6 -> 45784 | AD6: =+AJ6-1 -> 45829 | AE6: 45 | AF6: =+IF(V6=0,U6,V6)+AE6 -> 82 | AH6: =+AF6-AD6 -> -45747 | AJ6: =+AK6-AL6 -> 45830 | AK6: =+AV6-1 -> 45844 | AL6: 14 | AM6: =+IF(AG6=0,AF6,AG6)+AL6 -> 96 | AO6: =+AM6-AK6 -> -45748 | AV6: =+AW6-AX6 -> 45845 | AW6: =+BQ6-1 -> 46145 | AX6: 300 | AY6: =+IF(AN6=0,AM6,AN6)+AX6 -> 396 | BA6: =+AY6-AW6 -> -45749 | BC6: =+BD6-BE6 -> 46146 | BD6: =+BJ6 -> 46146 | BE6: 0 | BF6: =+IF(AZ6=0,AY6,AZ6)+BE6 -> 396 | BH6: =+BF6-BD6 -> -45750 | BJ6: =+BK6-BL6 -> 46146 | BK6: =+BQ6 -> 46146 | BL6: 0 | BM6: =+IF(BG6=0,BF6,BG6)+BL6 -> 396 | BO6: =+BM6-BK6 -> -45750 | BQ6: =+BR6-BS6 -> 46146 | BR6: =+BX6 -> 46153 | BS6: 7 | BT6: =+IF(BN6=0,BM6,BN6)+BS6 -> 403 | BV6: =+BT6-BR6 -> -45750 | BX6: 46153 | BY6: =+BT6-BX6 -> -45750 | CA6: Fecha de equipos estáticos y paquetes crono 4/11/24
A7: EM-Mecánica | C7: Filtro de gas combustible | E7: =+J7-1 -> 45794 | H7: =+F7-E7 -> -45794 | J7: =+K7-L7 -> 45795 | K7: =+R7-1 -> 45802 | L7: 7 | M7: =+F7+L7 -> 7 | O7: =+M7-K7 -> -45795 | R7: =+S7-T7 -> 45803 | S7: =+AC7-1 -> 45833 | T7: 30 | U7: =+M7+T7 -> 37 | W7: =+U7-S7 -> -45796 | AC7: =+AD7-AE7 -> 45834 | AD7: =+AJ7-1 -> 45879 | AE7: 45 | AF7: =+IF(V7=0,U7,V7)+AE7 -> 82 | AH7: =+AF7-AD7 -> -45797 | AJ7: =+AK7-AL7 -> 45880 | AK7: =+AV7-1 -> 45894 | AL7: 14 | AM7: =+IF(AG7=0,AF7,AG7)+AL7 -> 96 | AO7: =+AM7-AK7 -> -45798 | AV7: =+AW7-AX7 -> 45895 | AW7: =+BQ7-1 -> 46145 | AX7: 250 | AY7: =+IF(AN7=0,AM7,AN7)+AX7 -> 346 | BA7: =+AY7-AW7 -> -45799 | BC7: =+BD7-BE7 -> 46146 | BD7: =+BJ7 -> 46146 | BE7: 0 | BF7: =+IF(AZ7=0,AY7,AZ7)+BE7 -> 346 | BH7: =+BF7-BD7 -> -45800 | BJ7: =+BK7-BL7 -> 46146 | BK7: =+BQ7 -> 46146 | BL7: 0 | BM7: =+IF(BG7=0,BF7,BG7)+BL7 -> 346 | BO7: =+BM7-BK7 -> -45800 | BQ7: =+BR7-BS7 -> 46146 | BR7: =+BX7 -> 46153 | BS7: 7 | BT7: =+IF(BN7=0,BM7,BN7)+BS7 -> 353 | BV7: =+BT7-BR7 -> -45800 | BX7: 46153 | BY7: =+BT7-BX7 -> -45800 | CA7: Fecha de equipos estáticos y paquetes crono 4/11/24
A8: EM-Mecánica | C8: Compresor/Secador de aire | E8: =+J8-1 -> 45794 | H8: =+F8-E8 -> -45794 | J8: =+K8-L8 -> 45795 | K8: =+R8-1 -> 45802 | L8: 7 | M8: =+F8+L8 -> 7 | O8: =+M8-K8 -> -45795 | R8: =+S8-T8 -> 45803 | S8: =+AC8-1 -> 45833 | T8: 30 | U8: =+M8+T8 -> 37 | W8: =+U8-S8 -> -45796 | AC8: =+AD8-AE8 -> 45834 | AD8: =+AJ8-1 -> 45879 | AE8: 45 | AF8: =+IF(V8=0,U8,V8)+AE8 -> 82 | AH8: =+AF8-AD8 -> -45797 | AJ8: =+AK8-AL8 -> 45880 | AK8: =+AV8-1 -> 45894 | AL8: 14 | AM8: =+IF(AG8=0,AF8,AG8)+AL8 -> 96 | AO8: =+AM8-AK8 -> -45798 | AV8: =+AW8-AX8 -> 45895 | AW8: =+BQ8-1 -> 46145 | AX8: 250 | AY8: =+IF(AN8=0,AM8,AN8)+AX8 -> 346 | BA8: =+AY8-AW8 -> -45799 | BC8: =+BD8-BE8 -> 46146 | BD8: =+BJ8 -> 46146 | BE8: 0 | BF8: =+IF(AZ8=0,AY8,AZ8)+BE8 -> 346 | BH8: =+BF8-BD8 -> -45800 | BJ8: =+BK8-BL8 -> 46146 | BK8: =+BQ8 -> 46146 | BL8: 0 | BM8: =+IF(BG8=0,BF8,BG8)+BL8 -> 346 | BO8: =+BM8-BK8 -> -45800 | BQ8: =+BR8-BS8 -> 46146 | BR8: =+BX8 -> 46153 | BS8: 7 | BT8: =+IF(BN8=0,BM8,BN8)+BS8 -> 353 | BV8: =+BT8-BR8 -> -45800 | BX8: 46153 | BY8: =+BT8-BX8 -> -45800 | CA8: Fecha de equipos estáticos y paquetes crono 4/11/24
A9: EM-Mecánica | C9: Filtro de aire | E9: =+J9-1 -> 45804 | H9: =+F9-E9 -> -45804 | J9: =+K9-L9 -> 45805 | K9: =+R9-1 -> 45812 | L9: 7 | M9: =+F9+L9 -> 7 | O9: =+M9-K9 -> -45805 | R9: =+S9-T9 -> 45813 | S9: =+AC9-1 -> 45843 | T9: 30 | U9: =+M9+T9 -> 37 | W9: =+U9-S9 -> -45806 | AC9: =+AD9-AE9 -> 45844 | AD9: =+AJ9-1 -> 45889 | AE9: 45 | AF9: =+IF(V9=0,U9,V9)+AE9 -> 82 | AH9: =+AF9-AD9 -> -45807 | AJ9: =+AK9-AL9 -> 45890 | AK9: =+AV9-1 -> 45904 | AL9: 14 | AM9: =+IF(AG9=0,AF9,AG9)+AL9 -> 96 | AO9: =+AM9-AK9 -> -45808 | AV9: =+AW9-AX9 -> 45905 | AW9: =+BQ9-1 -> 46145 | AX9: 240 | AY9: =+IF(AN9=0,AM9,AN9)+AX9 -> 336 | BA9: =+AY9-AW9 -> -45809 | BC9: =+BD9-BE9 -> 46146 | BD9: =+BJ9 -> 46146 | BE9: 0 | BF9: =+IF(AZ9=0,AY9,AZ9)+BE9 -> 336 | BH9: =+BF9-BD9 -> -45810 | BJ9: =+BK9-BL9 -> 46146 | BK9: =+BQ9 -> 46146 | BL9: 0 | BM9: =+IF(BG9=0,BF9,BG9)+BL9 -> 336 | BO9: =+BM9-BK9 -> -45810 | BQ9: =+BR9-BS9 -> 46146 | BR9: =+BX9 -> 46153 | BS9: 7 | BT9: =+IF(BN9=0,BM9,BN9)+BS9 -> 343 | BV9: =+BT9-BR9 -> -45810 | BX9: 46153 | BY9: =+BT9-BX9 -> -45810 | CA9: Fecha de equipos estáticos y paquetes crono 4/11/24
A10: EM-Mecánica | C10: Enfriador de aire | E10: =+J10-1 -> 45774 | H10: =+F10-E10 -> -45774 | J10: =+K10-L10 -> 45775 | K10: =+R10-1 -> 45782 | L10: 7 | M10: =+F10+L10 -> 7 | O10: =+M10-K10 -> -45775 | R10: =+S10-T10 -> 45783 | S10: =+AC10-1 -> 45813 | T10: 30 | U10: =+M10+T10 -> 37 | W10: =+U10-S10 -> -45776 | AC10: =+AD10-AE10 -> 45814 | AD10: =+AJ10-1 -> 45859 | AE10: 45 | AF10: =+IF(V10=0,U10,V10)+AE10 -> 82 | AH10: =+AF10-AD10 -> -45777 | AJ10: =+AK10-AL10 -> 45860 | AK10: =+AV10-1 -> 45874 | AL10: 14 | AM10: =+IF(AG10=0,AF10,AG10)+AL10 -> 96 | AO10: =+AM10-AK10 -> -45778 | AV10: =+AW10-AX10 -> 45875 | AW10: =+BQ10-1 -> 46145 | AX10: 270 | AY10: =+IF(AN10=0,AM10,AN10)+AX10 -> 366 | BA10: =+AY10-AW10 -> -45779 | BC10: =+BD10-BE10 -> 46146 | BD10: =+BJ10 -> 46146 | BE10: 0 | BF10: =+IF(AZ10=0,AY10,AZ10)+BE10 -> 366 | BH10: =+BF10-BD10 -> -45780 | BJ10: =+BK10-BL10 -> 46146 | BK10: =+BQ10 -> 46146 | BL10: 0 | BM10: =+IF(BG10=0,BF10,BG10)+BL10 -> 366 | BO10: =+BM10-BK10 -> -45780 | BQ10: =+BR10-BS10 -> 46146 | BR10: =+BX10 -> 46153 | BS10: 7 | BT10: =+IF(BN10=0,BM10,BN10)+BS10 -> 373 | BV10: =+BT10-BR10 -> -45780 | BX10: 46153 | BY10: =+BT10-BX10 -> -45780 | CA10: Fecha de equipos estáticos y paquetes crono 4/11/24
A11: EM-Mecánica | C11: Skid generación de nitrógeno | E11: =+J11-1 -> 45714 | H11: =+F11-E11 -> -45714 | J11: =+K11-L11 -> 45715 | K11: =+R11-1 -> 45722 | L11: 7 | M11: =+F11+L11 -> 7 | O11: =+M11-K11 -> -45715 | R11: =+S11-T11 -> 45723 | S11: =+AC11-1 -> 45753 | T11: 30 | U11: =+M11+T11 -> 37 | W11: =+U11-S11 -> -45716 | AC11: =+AD11-AE11 -> 45754 | AD11: =+AJ11-1 -> 45799 | AE11: 45 | AF11: =+IF(V11=0,U11,V11)+AE11 -> 82 | AH11: =+AF11-AD11 -> -45717 | AJ11: =+AK11-AL11 -> 45800 | AK11: =+AV11-1 -> 45814 | AL11: 14 | AM11: =+IF(AG11=0,AF11,AG11)+AL11 -> 96 | AO11: =+AM11-AK11 -> -45718 | AV11: =+AW11-AX11 -> 45815 | AW11: =+BQ11-1 -> 46145 | AX11: 330 | AY11: =+IF(AN11=0,AM11,AN11)+AX11 -> 426 | BA11: =+AY11-AW11 -> -45719 | BC11: =+BD11-BE11 -> 46146 | BD11: =+BJ11 -> 46146 | BE11: 0 | BF11: =+IF(AZ11=0,AY11,AZ11)+BE11 -> 426 | BH11: =+BF11-BD11 -> -45720 | BJ11: =+BK11-BL11 -> 46146 | BK11: =+BQ11 -> 46146 | BL11: 0 | BM11: =+IF(BG11=0,BF11,BG11)+BL11 -> 426 | BO11: =+BM11-BK11 -> -45720 | BQ11: =+BR11-BS11 -> 46146 | BR11: =+BX11 -> 46153 | BS11: 7 | BT11: =+IF(BN11=0,BM11,BN11)+BS11 -> 433 | BV11: =+BT11-BR11 -> -45720 | BX11: 46153 | BY11: =+BT11-BX11 -> -45720 | CA11: Fecha de equipos estáticos y paquetes crono 4/11/24
A12: EM-Mecánica | C12: Calentador de gas combustible AP | E12: =+J12-1 -> 45714 | H12: =+F12-E12 -> -45714 | J12: =+K12-L12 -> 45715 | K12: =+R12-1 -> 45722 | L12: 7 | M12: =+F12+L12 -> 7 | O12: =+M12-K12 -> -45715 | R12: =+S12-T12 -> 45723 | S12: =+AC12-1 -> 45753 | T12: 30 | U12: =+M12+T12 -> 37 | W12: =+U12-S12 -> -45716 | AC12: =+AD12-AE12 -> 45754 | AD12: =+AJ12-1 -> 45799 | AE12: 45 | AF12: =+IF(V12=0,U12,V12)+AE12 -> 82 | AH12: =+AF12-AD12 -> -45717 | AJ12: =+AK12-AL12 -> 45800 | AK12: =+AV12-1 -> 45814 | AL12: 14 | AM12: =+IF(AG12=0,AF12,AG12)+AL12 -> 96 | AO12: =+AM12-AK12 -> -45718 | AV12: =+AW12-AX12 -> 45815 | AW12: =+BQ12-1 -> 46145 | AX12: 330 | AY12: =+IF(AN12=0,AM12,AN12)+AX12 -> 426 | BA12: =+AY12-AW12 -> -45719 | BC12: =+BD12-BE12 -> 46146 | BD12: =+BJ12 -> 46146 | BE12: 0 | BF12: =+IF(AZ12=0,AY12,AZ12)+BE12 -> 426 | BH12: =+BF12-BD12 -> -45720 | BJ12: =+BK12-BL12 -> 46146 | BK12: =+BQ12 -> 46146 | BL12: 0 | BM12: =+IF(BG12=0,BF12,BG12)+BL12 -> 426 | BO12: =+BM12-BK12 -> -45720 | BQ12: =+BR12-BS12 -> 46146 | BR12: =+BX12 -> 46153 | BS12: 7 | BT12: =+IF(BN12=0,BM12,BN12)+BS12 -> 433 | BV12: =+BT12-BR12 -> -45720 | BX12: 46153 | BY12: =+BT12-BX12 -> -45720 | CA12: Fecha de equipos estáticos y paquetes crono 4/11/24
A13: EM-Mecánica | C13: Skid de inyección de químicos (tanque + bombas) | E13: =+J13-1 -> 45834 | H13: =+F13-E13 -> -45834 | J13: =+K13-L13 -> 45835 | K13: =+R13-1 -> 45842 | L13: 7 | M13: =+F13+L13 -> 7 | O13: =+M13-K13 -> -45835 | R13: =+S13-T13 -> 45843 | S13: =+AC13-1 -> 45873 | T13: 30 | U13: =+M13+T13 -> 37 | W13: =+U13-S13 -> -45836 | AC13: =+AD13-AE13 -> 45874 | AD13: =+AJ13-1 -> 45919 | AE13: 45 | AF13: =+IF(V13=0,U13,V13)+AE13 -> 82 | AH13: =+AF13-AD13 -> -45837 | AJ13: =+AK13-AL13 -> 45920 | AK13: =+AV13-1 -> 45934 | AL13: 14 | AM13: =+IF(AG13=0,AF13,AG13)+AL13 -> 96 | AO13: =+AM13-AK13 -> -45838 | AV13: =+AW13-AX13 -> 45935 | AW13: =+BQ13-1 -> 46145 | AX13: 210 | AY13: =+IF(AN13=0,AM13,AN13)+AX13 -> 306 | BA13: =+AY13-AW13 -> -45839 | BC13: =+BD13-BE13 -> 46146 | BD13: =+BJ13 -> 46146 | BE13: 0 | BF13: =+IF(AZ13=0,AY13,AZ13)+BE13 -> 306 | BH13: =+BF13-BD13 -> -45840 | BJ13: =+BK13-BL13 -> 46146 | BK13: =+BQ13 -> 46146 | BL13: 0 | BM13: =+IF(BG13=0,BF13,BG13)+BL13 -> 306 | BO13: =+BM13-BK13 -> -45840 | BQ13: =+BR13-BS13 -> 46146 | BR13: =+BX13 -> 46153 | BS13: 7 | BT13: =+IF(BN13=0,BM13,BN13)+BS13 -> 313 | BV13: =+BT13-BR13 -> -45840 | BX13: 46153 | BY13: =+BT13-BX13 -> -45840 | CA13: Fecha de equipos estáticos y paquetes crono 4/11/24
A14: EM-Mecánica | C14: Separador de condensados de EPF | E14: =+J14-1 -> 45714 | H14: =+F14-E14 -> -45714 | J14: =+K14-L14 -> 45715 | K14: =+R14-1 -> 45722 | L14: 7 | M14: =+F14+L14 -> 7 | O14: =+M14-K14 -> -45715 | R14: =+S14-T14 -> 45723 | S14: =+AC14-1 -> 45753 | T14: 30 | U14: =+M14+T14 -> 37 | W14: =+U14-S14 -> -45716 | AC14: =+AD14-AE14 -> 45754 | AD14: =+AJ14-1 -> 45799 | AE14: 45 | AF14: =+IF(V14=0,U14,V14)+AE14 -> 82 | AH14: =+AF14-AD14 -> -45717 | AJ14: =+AK14-AL14 -> 45800 | AK14: =+AV14-1 -> 45814 | AL14: 14 | AM14: =+IF(AG14=0,AF14,AG14)+AL14 -> 96 | AO14: =+AM14-AK14 -> -45718 | AV14: =+AW14-AX14 -> 45815 | AW14: =+BQ14-1 -> 46145 | AX14: 330 | AY14: =+IF(AN14=0,AM14,AN14)+AX14 -> 426 | BA14: =+AY14-AW14 -> -45719 | BC14: =+BD14-BE14 -> 46146 | BD14: =+BJ14 -> 46146 | BE14: 0 | BF14: =+IF(AZ14=0,AY14,AZ14)+BE14 -> 426 | BH14: =+BF14-BD14 -> -45720 | BJ14: =+BK14-BL14 -> 46146 | BK14: =+BQ14 -> 46146 | BL14: 0 | BM14: =+IF(BG14=0,BF14,BG14)+BL14 -> 426 | BO14: =+BM14-BK14 -> -45720 | BQ14: =+BR14-BS14 -> 46146 | BR14: =+BX14 -> 46153 | BS14: 7 | BT14: =+IF(BN14=0,BM14,BN14)+BS14 -> 433 | BV14: =+BT14-BR14 -> -45720 | BX14: 46153 | BY14: =+BT14-BX14 -> -45720 | CA14: Fecha de equipos estáticos y paquetes crono 4/11/24
A15: EM-Mecánica | C15: Tanque de almacenamiento de agua de inyección | E15: =+J15-1 -> 45764 | H15: =+F15-E15 -> -45764 | J15: =+K15-L15 -> 45765 | K15: =+R15-1 -> 45772 | L15: 7 | M15: =+F15+L15 -> 7 | O15: =+M15-K15 -> -45765 | R15: =+S15-T15 -> 45773 | S15: =+AC15-1 -> 45803 | T15: 30 | U15: =+M15+T15 -> 37 | W15: =+U15-S15 -> -45766 | AC15: =+AD15-AE15 -> 45804 | AD15: =+AJ15-1 -> 45849 | AE15: 45 | AF15: =+IF(V15=0,U15,V15)+AE15 -> 82 | AH15: =+AF15-AD15 -> -45767 | AJ15: =+AK15-AL15 -> 45850 | AK15: =+AV15-1 -> 45864 | AL15: 14 | AM15: =+IF(AG15=0,AF15,AG15)+AL15 -> 96 | AO15: =+AM15-AK15 -> -45768 | AV15: =+AW15-AX15 -> 45865 | AW15: =+BQ15-1 -> 46145 | AX15: 280 | AY15: =+IF(AN15=0,AM15,AN15)+AX15 -> 376 | BA15: =+AY15-AW15 -> -45769 | BC15: =+BD15-BE15 -> 46146 | BD15: =+BJ15 -> 46146 | BE15: 0 | BF15: =+IF(AZ15=0,AY15,AZ15)+BE15 -> 376 | BH15: =+BF15-BD15 -> -45770 | BJ15: =+BK15-BL15 -> 46146 | BK15: =+BQ15 -> 46146 | BL15: 0 | BM15: =+IF(BG15=0,BF15,BG15)+BL15 -> 376 | BO15: =+BM15-BK15 -> -45770 | BQ15: =+BR15-BS15 -> 46146 | BR15: =+BX15 -> 46153 | BS15: 7 | BT15: =+IF(BN15=0,BM15,BN15)+BS15 -> 383 | BV15: =+BT15-BR15 -> -45770 | BX15: 46153 | BY15: =+BT15-BX15 -> -45770 | CA15: Fecha de equipos estáticos y paquetes crono 4/11/24
A16: EM-Mecánica | C16: Filtro para bombas | E16: =+J16-1 -> 45804 | H16: =+F16-E16 -> -45804 | J16: =+K16-L16 -> 45805 | K16: =+R16-1 -> 45812 | L16: 7 | M16: =+F16+L16 -> 7 | O16: =+M16-K16 -> -45805 | R16: =+S16-T16 -> 45813 | S16: =+AC16-1 -> 45843 | T16: 30 | U16: =+M16+T16 -> 37 | W16: =+U16-S16 -> -45806 | AC16: =+AD16-AE16 -> 45844 | AD16: =+AJ16-1 -> 45889 | AE16: 45 | AF16: =+IF(V16=0,U16,V16)+AE16 -> 82 | AH16: =+AF16-AD16 -> -45807 | AJ16: =+AK16-AL16 -> 45890 | AK16: =+AV16-1 -> 45904 | AL16: 14 | AM16: =+IF(AG16=0,AF16,AG16)+AL16 -> 96 | AO16: =+AM16-AK16 -> -45808 | AV16: =+AW16-AX16 -> 45905 | AW16: =+BQ16-1 -> 46145 | AX16: 240 | AY16: =+IF(AN16=0,AM16,AN16)+AX16 -> 336 | BA16: =+AY16-AW16 -> -45809 | BC16: =+BD16-BE16 -> 46146 | BD16: =+BJ16 -> 46146 | BE16: 0 | BF16: =+IF(AZ16=0,AY16,AZ16)+BE16 -> 336 | BH16: =+BF16-BD16 -> -45810 | BJ16: =+BK16-BL16 -> 46146 | BK16: =+BQ16 -> 46146 | BL16: 0 | BM16: =+IF(BG16=0,BF16,BG16)+BL16 -> 336 | BO16: =+BM16-BK16 -> -45810 | BQ16: =+BR16-BS16 -> 46146 | BR16: =+BX16 -> 46153 | BS16: 7 | BT16: =+IF(BN16=0,BM16,BN16)+BS16 -> 343 | BV16: =+BT16-BR16 -> -45810 | BX16: 46153 | BY16: =+BT16-BX16 -> -45810 | CA16: Fecha de equipos estáticos y paquetes crono 4/11/24
... A62: IN-Instrumentación | C62: Cables de instrumentación Rev. 0 - Ingeniería inicial | E62: =+J62-1 -> 45900 | H62: =+F62-E62 -> -45900 | J62: =+K62-L62 -> 45901 | K62: =+R62-1 -> 45908 | L62: 7 | M62: =+F62+L62 -> 7 | O62: =+M62-K62 -> -45901 | R62: =+S62-T62 -> 45909 | S62: =+AC62-1 -> 45934 | T62: 25 | U62: =+M62+T62 -> 32 | W62: =+U62-S62 -> -45902 | AC62: =+AD62-AE62 -> 45935 | AD62: =+AJ62-1 -> 45980 | AE62: 45 | AF62: =+IF(V62=0,U62,V62)+AE62 -> 77 | AH62: =+AF62-AD62 -> -45903 | AJ62: =+AK62-AL62 -> 45981 | AK62: =+AV62-1 -> 45995 | AL62: 14 | AM62: =+IF(AG62=0,AF62,AG62)+AL62 -> 91 | AO62: =+AM62-AK62 -> -45904 | AV62: =+AW62-AX62 -> 45996 | AW62: =+BQ62-1 -> 46176 | AX62: 180 | AY62: =+IF(AN62=0,AM62,AN62)+AX62 -> 271 | BA62: =+AY62-AW62 -> -45905 | BC62: =+BD62-BE62 -> 46177 | BD62: =+BJ62 -> 46177 | BE62: 0 | BF62: =+IF(AZ62=0,AY62,AZ62)+BE62 -> 271 | BH62: =+BF62-BD62 -> -45906 | BJ62: =+BK62-BL62 -> 46177 | BK62: =+BQ62 -> 46177 | BL62: 0 | BM62: =+IF(BG62=0,BF62,BG62)+BL62 -> 271 | BO62: =+BM62-BK62 -> -45906 | BQ62: =+BR62-BS62 -> 46177 | BR62: =+BX62 -> 46184 | BS62: 7 | BT62: =+IF(BN62=0,BM62,BN62)+BS62 -> 278 | BV62: =+BT62-BR62 -> -45906 | BX62: 46184 | BY62: =+BT62-BX62 -> -45906 | CA62: Considero fecha inicio tendido de cables instrumentación
A63: IN-Instrumentación | C63: Cables de instrumentación Rev. 1 - Ingeniería 80% | E63: =+J63-1 -> 46041 | F63: =+C85 -> 46168 | H63: =+F63-E63 -> 127 | J63: =+K63-L63 -> 46042 | K63: =+R63-1 -> 46049 | L63: 7 | M63: =+F63+L63 -> 46175 | O63: =+M63-K63 -> 126 | R63: =+S63-T63 -> 46050 | S63: =+AC63-1 -> 46075 | T63: 25 | U63: =+M63+T63 -> 46200 | W63: =+U63-S63 -> 125 | AC63: =+AD63-AE63 -> 46076 | AD63: =+AJ63-1 -> 46121 | AE63: 45 | AF63: =+IF(V63=0,U63,V63)+AE63 -> 46245 | AH63: =+AF63-AD63 -> 124 | AJ63: =+AK63-AL63 -> 46122 | AK63: =+AV63-1 -> 46136 | AL63: 14 | AM63: =+IF(AG63=0,AF63,AG63)+AL63 -> 46259 | AO63: =+AM63-AK63 -> 123 | AV63: =+AW63-AX63 -> 46137 | AW63: =+BQ63-1 -> 46257 | AX63: 120 | AY63: =+IF(AN63=0,AM63,AN63)+AX63 -> 46379 | BA63: =+AY63-AW63 -> 122 | BC63: =+BD63-BE63 -> 46258 | BD63: =+BJ63 -> 46258 | BE63: 0 | BF63: =+IF(AZ63=0,AY63,AZ63)+BE63 -> 46379 | BH63: =+BF63-BD63 -> 121 | BJ63: =+BK63-BL63 -> 46258 | BK63: =+BQ63 -> 46258 | BL63: 0 | BM63: =+IF(BG63=0,BF63,BG63)+BL63 -> 46379 | BO63: =+BM63-BK63 -> 121 | BQ63: =+BR63-BS63 -> 46258 | BR63: =+BX63 -> 46265 | BS63: 7 | BT63: =+IF(BN63=0,BM63,BN63)+BS63 -> 46386 | BV63: =+BT63-BR63 -> 121 | BX63: 46265 | BY63: =+BT63-BX63 -> 121 | CA63: Considero fin de entrega de cables de acuerdo a crono 4.11
A64: IN-Instrumentación | C64: Sistema de control, hardware y software | E64: =+J64-1 -> 45967 | H64: =+F64-E64 -> -45967 | J64: =+K64-L64 -> 45968 | K64: =+R64-1 -> 45975 | L64: 7 | M64: =+F64+L64 -> 7 | O64: =+M64-K64 -> -45968 | R64: =+S64-T64 -> 45976 | S64: =+AC64-1 -> 46001 | T64: 25 | U64: =+M64+T64 -> 32 | W64: =+U64-S64 -> -45969 | AC64: =+AD64-AE64 -> 46002 | AD64: =+AJ64-1 -> 46047 | AE64: 45 | AF64: =+IF(V64=0,U64,V64)+AE64 -> 77 | AH64: =+AF64-AD64 -> -45970 | AJ64: =+AK64-AL64 -> 46048 | AK64: =+AV64-1 -> 46062 | AL64: 14 | AM64: =+IF(AG64=0,AF64,AG64)+AL64 -> 91 | AO64: =+AM64-AK64 -> -45971 | AV64: =+AW64-AX64 -> 46063 | AW64: =+BQ64-1 -> 46363 | AX64: 300 | AY64: =+IF(AN64=0,AM64,AN64)+AX64 -> 391 | BA64: =+AY64-AW64 -> -45972 | BC64: =+BD64-BE64 -> 46364 | BD64: =+BJ64 -> 46364 | BE64: 0 | BF64: =+IF(AZ64=0,AY64,AZ64)+BE64 -> 391 | BH64: =+BF64-BD64 -> -45973 | BJ64: =+BK64-BL64 -> 46364 | BK64: =+BQ64 -> 46364 | BL64: 0 | BM64: =+IF(BG64=0,BF64,BG64)+BL64 -> 391 | BO64: =+BM64-BK64 -> -45973 | BQ64: =+BR64-BS64 -> 46364 | BR64: =+BX64 -> 46371 | BS64: 7 | BT64: =+IF(BN64=0,BM64,BN64)+BS64 -> 398 | BV64: =+BT64-BR64 -> -45973 | BX64: 46371 | BY64: =+BT64-BX64 -> -45973 | CA64: Considero FE transmisores crono 4.11
A65: IN-Instrumentación | C65: Sistema fire & gas | E65: =+J65-1 -> 46027 | H65: =+F65-E65 -> -46027 | J65: =+K65-L65 -> 46028 | K65: =+R65-1 -> 46035 | L65: 7 | M65: =+F65+L65 -> 7 | O65: =+M65-K65 -> -46028 | R65: =+S65-T65 -> 46036 | S65: =+AC65-1 -> 46061 | T65: 25 | U65: =+M65+T65 -> 32 | W65: =+U65-S65 -> -46029 | AC65: =+AD65-AE65 -> 46062 | AD65: =+AJ65-1 -> 46107 | AE65: 45 | AF65: =+IF(V65=0,U65,V65)+AE65 -> 77 | AH65: =+AF65-AD65 -> -46030 | AJ65: =+AK65-AL65 -> 46108 | AK65: =+AV65-1 -> 46122 | AL65: 14 | AM65: =+IF(AG65=0,AF65,AG65)+AL65 -> 91 | AO65: =+AM65-AK65 -> -46031 | AV65: =+AW65-AX65 -> 46123 | AW65: =+BQ65-1 -> 46363 | AX65: 240 | AY65: =+IF(AN65=0,AM65,AN65)+AX65 -> 331 | BA65: =+AY65-AW65 -> -46032 | BC65: =+BD65-BE65 -> 46364 | BD65: =+BJ65 -> 46364 | BE65: 0 | BF65: =+IF(AZ65=0,AY65,AZ65)+BE65 -> 331 | BH65: =+BF65-BD65 -> -46033 | BJ65: =+BK65-BL65 -> 46364 | BK65: =+BQ65 -> 46364 | BL65: 0 | BM65: =+IF(BG65=0,BF65,BG65)+BL65 -> 331 | BO65: =+BM65-BK65 -> -46033 | BQ65: =+BR65-BS65 -> 46364 | BR65: =+BX65 -> 46371 | BS65: 7 | BT65: =+IF(BN65=0,BM65,BN65)+BS65 -> 338 | BV65: =+BT65-BR65 -> -46033 | BX65: 46371 | BY65: =+BT65-BX65 -> -46033 | CA65: Considero FE transmisores crono 4.11
A66: IN-Instrumentación | C66: Sistema contra incendio | E66: =+J66-1 -> 46027 | H66: =+F66-E66 -> -46027 | J66: =+K66-L66 -> 46028 | K66: =+R66-1 -> 46035 | L66: 7 | M66: =+F66+L66 -> 7 | O66: =+M66-K66 -> -46028 | R66: =+S66-T66 -> 46036 | S66: =+AC66-1 -> 46061 | T66: 25 | U66: =+M66+T66 -> 32 | W66: =+U66-S66 -> -46029 | AC66: =+AD66-AE66 -> 46062 | AD66: =+AJ66-1 -> 46107 | AE66: 45 | AF66: =+IF(V66=0,U66,V66)+AE66 -> 77 | AH66: =+AF66-AD66 -> -46030 | AJ66: =+AK66-AL66 -> 46108 | AK66: =+AV66-1 -> 46122 | AL66: 14 | AM66: =+IF(AG66=0,AF66,AG66)+AL66 -> 91 | AO66: =+AM66-AK66 -> -46031 | AV66: =+AW66-AX66 -> 46123 | AW66: =+BQ66-1 -> 46363 | AX66: 240 | AY66: =+IF(AN66=0,AM66,AN66)+AX66 -> 331 | BA66: =+AY66-AW66 -> -46032 | BC66: =+BD66-BE66 -> 46364 | BD66: =+BJ66 -> 46364 | BE66: 0 | BF66: =+IF(AZ66=0,AY66,AZ66)+BE66 -> 331 | BH66: =+BF66-BD66 -> -46033 | BJ66: =+BK66-BL66 -> 46364 | BK66: =+BQ66 -> 46364 | BL66: 0 | BM66: =+IF(BG66=0,BF66,BG66)+BL66 -> 331 | BO66: =+BM66-BK66 -> -46033 | BQ66: =+BR66-BS66 -> 46364 | BR66: =+BX66 -> 46371 | BS66: 7 | BT66: =+IF(BN66=0,BM66,BN66)+BS66 -> 338 | BV66: =+BT66-BR66 -> -46033 | BX66: 46371 | BY66: =+BT66-BX66 -> -46033 | CA66: Considero FE transmisores crono 4.11
A67: EL-Electricidad | C67: Shelter y banco de carga | E67: =+J67-1 -> 45948 | H67: =+F67-E67 -> -45948 | J67: =+K67-L67 -> 45949 | K67: =+R67-1 -> 45956 | L67: 7 | M67: =+F67+L67 -> 7 | O67: =+M67-K67 -> -45949 | R67: =+S67-T67 -> 45957 | S67: =+AC67-1 -> 45982 | T67: 25 | U67: =+M67+T67 -> 32 | W67: =+U67-S67 -> -45950 | AC67: =+AD67-AE67 -> 45983 | AD67: =+AJ67-1 -> 46028 | AE67: 45 | AF67: =+IF(V67=0,U67,V67)+AE67 -> 77 | AH67: =+AF67-AD67 -> -45951 | AJ67: =+AK67-AL67 -> 46029 | AK67: =+AV67-1 -> 46043 | AL67: 14 | AM67: =+IF(AG67=0,AF67,AG67)+AL67 -> 91 | AO67: =+AM67-AK67 -> -45952 | AV67: =+AW67-AX67 -> 46044 | AW67: =+BQ67-1 -> 46344 | AX67: 300 | AY67: =+IF(AN67=0,AM67,AN67)+AX67 -> 391 | BA67: =+AY67-AW67 -> -45953 | BC67: =+BD67-BE67 -> 46345 | BD67: =+BJ67 -> 46345 | BE67: 0 | BF67: =+IF(AZ67=0,AY67,AZ67)+BE67 -> 391 | BH67: =+BF67-BD67 -> -45954 | BJ67: =+BK67-BL67 -> 46345 | BK67: =+BQ67 -> 46345 | BL67: 0 | BM67: =+IF(BG67=0,BF67,BG67)+BL67 -> 391 | BO67: =+BM67-BK67 -> -45954 | BQ67: =+BR67-BS67 -> 46345 | BR67: =+BX67 -> 46352 | BS67: 7 | BT67: =+IF(BN67=0,BM67,BN67)+BS67 -> 398 | BV67: =+BT67-BR67 -> -45954 | BX67: 46352 | BY67: =+BT67-BX67 -> -45954 | CA67: Considero fecha de entrega de acuerdo a crono 4.11
A68: EL-Electricidad | C68: Tableros y celdas MT | E68: =+J68-1 -> 45895 | H68: =+F68-E68 -> -45895 | J68: =+K68-L68 -> 45896 | K68: =+R68-1 -> 45903 | L68: 7 | M68: =+F68+L68 -> 7 | O68: =+M68-K68 -> -45896 | R68: =+S68-T68 -> 45904 | S68: =+AC68-1 -> 45929 | T68: 25 | U68: =+M68+T68 -> 32 | W68: =+U68-S68 -> -45897 | AC68: =+AD68-AE68 -> 45930 | AD68: =+AJ68-1 -> 45975 | AE68: 45 | AF68: =+IF(V68=0,U68,V68)+AE68 -> 77 | AH68: =+AF68-AD68 -> -45898 | AJ68: =+AK68-AL68 -> 45976 | AK68: =+AV68-1 -> 45990 | AL68: 14 | AM68: =+IF(AG68=0,AF68,AG68)+AL68 -> 91 | AO68: =+AM68-AK68 -> -45899 | AV68: =+AW68-AX68 -> 45991 | AW68: =+BQ68-1 -> 46351 | AX68: 360 | AY68: =+IF(AN68=0,AM68,AN68)+AX68 -> 451 | BA68: =+AY68-AW68 -> -45900 | BC68: =+BD68-BE68 -> 46352 | BD68: =+BJ68 -> 46352 | BE68: 0 | BF68: =+IF(AZ68=0,AY68,AZ68)+BE68 -> 451 | BH68: =+BF68-BD68 -> -45901 | BJ68: =+BK68-BL68 -> 46352 | BK68: =+BQ68 -> 46352 | BL68: 0 | BM68: =+IF(BG68=0,BF68,BG68)+BL68 -> 451 | BO68: =+BM68-BK68 -> -45901 | BQ68: =+BR68-BS68 -> 46352 | BR68: =+BX68 -> 46359 | BS68: 7 | BT68: =+IF(BN68=0,BM68,BN68)+BS68 -> 458 | BV68: =+BT68-BR68 -> -45901 | BX68: 46359 | BY68: =+BT68-BX68 -> -45901 | CA68: Considero fecha de entrega de acuerdo a crono 4.11
A69: EL-Electricidad | C69: Tableros BT y CCM | E69: =+J69-1 -> 45852 | H69: =+F69-E69 -> -45852 | J69: =+K69-L69 -> 45853 | K69: =+R69-1 -> 45860 | L69: 7 | M69: =+F69+L69 -> 7 | O69: =+M69-K69 -> -45853 | R69: =+S69-T69 -> 45861 | S69: =+AC69-1 -> 45886 | T69: 25 | U69: =+M69+T69 -> 32 | W69: =+U69-S69 -> -45854 | AC69: =+AD69-AE69 -> 45887 | AD69: =+AJ69-1 -> 45932 | AE69: 45 | AF69: =+IF(V69=0,U69,V69)+AE69 -> 77 | AH69: =+AF69-AD69 -> -45855 | AJ69: =+AK69-AL69 -> 45933 | AK69: =+AV69-1 -> 45947 | AL69: 14 | AM69: =+IF(AG69=0,AF69,AG69)+AL69 -> 91 | AO69: =+AM69-AK69 -> -45856 | AV69: =+AW69-AX69 -> 45948 | AW69: =+BQ69-1 -> 46308 | AX69: 360 | AY69: =+IF(AN69=0,AM69,AN69)+AX69 -> 451 | BA69: =+AY69-AW69 -> -45857 | BC69: =+BD69-BE69 -> 46309 | BD69: =+BJ69 -> 46309 | BE69: 0 | BF69: =+IF(AZ69=0,AY69,AZ69)+BE69 -> 451 | BH69: =+BF69-BD69 -> -45858 | BJ69: =+BK69-BL69 -> 46309 | BK69: =+BQ69 -> 46309 | BL69: 0 | BM69: =+IF(BG69=0,BF69,BG69)+BL69 -> 451 | BO69: =+BM69-BK69 -> -45858 | BQ69: =+BR69-BS69 -> 46309 | BR69: =+BX69 -> 46316 | BS69: 7 | BT69: =+IF(BN69=0,BM69,BN69)+BS69 -> 458 | BV69: =+BT69-BR69 -> -45858 | BX69: 46316 | BY69: =+BT69-BX69 -> -45858 | CA69: Considero fecha de entrega de acuerdo a crono 4.11
A70: EL-Electricidad | C70: Canalizaciones eléctricas | E70: =+J70-1 -> 45842 | H70: =+F70-E70 -> -45842 | J70: =+K70-L70 -> 45843 | K70: =+R70-1 -> 45850 | L70: 7 | M70: =+F70+L70 -> 7 | O70: =+M70-K70 -> -45843 | R70: =+S70-T70 -> 45851 | S70: =+AC70-1 -> 45876 | T70: 25 | U70: =+M70+T70 -> 32 | W70: =+U70-S70 -> -45844 | AC70: =+AD70-AE70 -> 45877 | AD70: =+AJ70-1 -> 45907 | AE70: 30 | AF70: =+IF(V70=0,U70,V70)+AE70 -> 62 | AH70: =+AF70-AD70 -> -45845 | AJ70: =+AK70-AL70 -> 45908 | AK70: =+AV70-1 -> 45922 | AL70: 14 | AM70: =+IF(AG70=0,AF70,AG70)+AL70 -> 76 | AO70: =+AM70-AK70 -> -45846 | AV70: =+AW70-AX70 -> 45923 | AW70: =+BQ70-1 -> 46043 | AX70: 120 | AY70: =+IF(AN70=0,AM70,AN70)+AX70 -> 196 | BA70: =+AY70-AW70 -> -45847 | BC70: =+BD70-BE70 -> 46044 | BD70: =+BJ70 -> 46044 | BE70: 0 | BF70: =+IF(AZ70=0,AY70,AZ70)+BE70 -> 196 | BH70: =+BF70-BD70 -> -45848 | BJ70: =+BK70-BL70 -> 46044 | BK70: =+BQ70 -> 46044 | BL70: 0 | BM70: =+IF(BG70=0,BF70,BG70)+BL70 -> 196 | BO70: =+BM70-BK70 -> -45848 | BQ70: =+BR70-BS70 -> 46044 | BR70: =+BX70 -> 46051 | BS70: 7 | BT70: =+IF(BN70=0,BM70,BN70)+BS70 -> 203 | BV70: =+BT70-BR70 -> -45848 | BX70: 46051 | BY70: =+BT70-BX70 -> -45848 | CA70: Considero fecha de entrega de acuerdo a crono 4.11
A71: EL-Electricidad | C71: Cables Rev. 0 - Ingeniería inicial | E71: =+J71-1 -> 45892 | H71: =+F71-E71 -> -45892 | J71: =+K71-L71 -> 45893 | K71: =+R71-1 -> 45900 | L71: 7 | M71: =+F71+L71 -> 7 | O71: =+M71-K71 -> -45893 | R71: =+S71-T71 -> 45901 | S71: =+AC71-1 -> 45926 | T71: 25 | U71: =+M71+T71 -> 32 | W71: =+U71-S71 -> -45894 | AC71: =+AD71-AE71 -> 45927 | AD71: =+AJ71-1 -> 45972 | AE71: 45 | AF71: =+IF(V71=0,U71,V71)+AE71 -> 77 | AH71: =+AF71-AD71 -> -45895 | AJ71: =+AK71-AL71 -> 45973 | AK71: =+AV71-1 -> 45987 | AL71: 14 | AM71: =+IF(AG71=0,AF71,AG71)+AL71 -> 91 | AO71: =+AM71-AK71 -> -45896 | AV71: =+AW71-AX71 -> 45988 | AW71: =+BQ71-1 -> 46168 | AX71: 180 | AY71: =+IF(AN71=0,AM71,AN71)+AX71 -> 271 | BA71: =+AY71-AW71 -> -45897 | BC71: =+BD71-BE71 -> 46169 | BD71: =+BJ71 -> 46169 | BE71: 0 | BF71: =+IF(AZ71=0,AY71,AZ71)+BE71 -> 271 | BH71: =+BF71-BD71 -> -45898 | BJ71: =+BK71-BL71 -> 46169 | BK71: =+BQ71 -> 46169 | BL71: 0 | BM71: =+IF(BG71=0,BF71,BG71)+BL71 -> 271 | BO71: =+BM71-BK71 -> -45898 | BQ71: =+BR71-BS71 -> 46169 | BR71: =+BX71 -> 46176 | BS71: 7 | BT71: =+IF(BN71=0,BM71,BN71)+BS71 -> 278 | BV71: =+BT71-BR71 -> -45898 | BX71: 46176 | BY71: =+BT71-BX71 -> -45898 | CA71: Considero fecha de entrega de acuerdo a crono 4.11
A72: EL-Electricidad | C72: Cables Rev. 1 - Ingeniería 80% | E72: =+J72-1 -> 46016 | F72: =+F63 -> 46168 | H72: =+F72-E72 -> 152 | J72: =+K72-L72 -> 46017 | K72: =+R72-1 -> 46024 | L72: 7 | M72: =+F72+L72 -> 46175 | O72: =+M72-K72 -> 151 | R72: =+S72-T72 -> 46025 | S72: =+AC72-1 -> 46050 | T72: 25 | U72: =+M72+T72 -> 46200 | W72: =+U72-S72 -> 150 | AC72: =+AD72-AE72 -> 46051 | AD72: =+AJ72-1 -> 46096 | AE72: 45 | AF72: =+IF(V72=0,U72,V72)+AE72 -> 46245 | AH72: =+AF72-AD72 -> 149 | AJ72: =+AK72-AL72 -> 46097 | AK72: =+AV72-1 -> 46111 | AL72: 14 | AM72: =+IF(AG72=0,AF72,AG72)+AL72 -> 46259 | AO72: =+AM72-AK72 -> 148 | AV72: =+AW72-AX72 -> 46112 | AW72: =+BQ72-1 -> 46232 | AX72: 120 | AY72: =+IF(AN72=0,AM72,AN72)+AX72 -> 46379 | BA72: =+AY72-AW72 -> 147 | BC72: =+BD72-BE72 -> 46233 | BD72: =+BJ72 -> 46233 | BE72: 0 | BF72: =+IF(AZ72=0,AY72,AZ72)+BE72 -> 46379 | BH72: =+BF72-BD72 -> 146 | BJ72: =+BK72-BL72 -> 46233 | BK72: =+BQ72 -> 46233 | BL72: 0 | BM72: =+IF(BG72=0,BF72,BG72)+BL72 -> 46379 | BO72: =+BM72-BK72 -> 146 | BQ72: =+BR72-BS72 -> 46233 | BR72: =+BX72 -> 46240 | BS72: 7 | BT72: =+IF(BN72=0,BM72,BN72)+BS72 -> 46386 | BV72: =+BT72-BR72 -> 146 | BX72: 46240 | BY72: =+BT72-BX72 -> 146 | CA72: Considero fecha de inicio de tendido de cables crono 4.11
A73: EL-Electricidad | C73: Materiales para PAT | E73: =+J73-1 -> 46130 | F73: =+F77 -> 45748 | H73: =+F73-E73 -> -382 | J73: =+K73-L73 -> 46131 | K73: =+R73-1 -> 46138 | L73: 7 | M73: =+F73+L73 -> 45755 | O73: =+M73-K73 -> -383 | R73: =+S73-T73 -> 46139 | S73: =+AC73-1 -> 46164 | T73: 25 | U73: =+M73+T73 -> 45780 | W73: =+U73-S73 -> -384 | AC73: =+AD73-AE73 -> 46165 | AD73: =+AJ73-1 -> 46195 | AE73: 30 | AF73: =+IF(V73=0,U73,V73)+AE73 -> 45810 | AH73: =+AF73-AD73 -> -385 | AJ73: =+AK73-AL73 -> 46196 | AK73: =+AV73-1 -> 46210 | AL73: 14 | AM73: =+IF(AG73=0,AF73,AG73)+AL73 -> 45824 | AO73: =+AM73-AK73 -> -386 | AV73: =+AW73-AX73 -> 46211 | AW73: =+BQ73-1 -> 46331 | AX73: 120 | AY73: =+IF(AN73=0,AM73,AN73)+AX73 -> 45944 | BA73: =+AY73-AW73 -> -387 | BC73: =+BD73-BE73 -> 46332 | BD73: =+BJ73 -> 46332 | BE73: 0 | BF73: =+IF(AZ73=0,AY73,AZ73)+BE73 -> 45944 | BH73: =+BF73-BD73 -> -388 | BJ73: =+BK73-BL73 -> 46332 | BK73: =+BQ73 -> 46332 | BL73: 0 | BM73: =+IF(BG73=0,BF73,BG73)+BL73 -> 45944 | BO73: =+BM73-BK73 -> -388 | BQ73: =+BR73-BS73 -> 46332 | BR73: =+BX73 -> 46339 | BS73: 7 | BT73: =+IF(BN73=0,BM73,BN73)+BS73 -> 45951 | BV73: =+BT73-BR73 -> -388 | BX73: 46339 | BY73: =+BT73-BX73 -> -388 | CA73: Considero fecha de entrega de acuerdo a crono 4.11
A74: EL-Electricidad | C74: Sistema UPS y rectificadores | E74: =+J74-1 -> 45962 | H74: =+F74-E74 -> -45962 | J74: =+K74-L74 -> 45963 | K74: =+R74-1 -> 45970 | L74: 7 | M74: =+F74+L74 -> 7 | O74: =+M74-K74 -> -45963 | R74: =+S74-T74 -> 45971 | S74: =+AC74-1 -> 45996 | T74: 25 | U74: =+M74+T74 -> 32 | W74: =+U74-S74 -> -45964 | AC74: =+AD74-AE74 -> 45997 | AD74: =+AJ74-1 -> 46042 | AE74: 45 | AF74: =+IF(V74=0,U74,V74)+AE74 -> 77 | AH74: =+AF74-AD74 -> -45965 | AJ74: =+AK74-AL74 -> 46043 | AK74: =+AV74-1 -> 46057 | AL74: 14 | AM74: =+IF(AG74=0,AF74,AG74)+AL74 -> 91 | AO74: =+AM74-AK74 -> -45966 | AV74: =+AW74-AX74 -> 46058 | AW74: =+BQ74-1 -> 46358 | AX74: 300 | AY74: =+IF(AN74=0,AM74,AN74)+AX74 -> 391 | BA74: =+AY74-AW74 -> -45967 | BC74: =+BD74-BE74 -> 46359 | BD74: =+BJ74 -> 46359 | BE74: 0 | BF74: =+IF(AZ74=0,AY74,AZ74)+BE74 -> 391 | BH74: =+BF74-BD74 -> -45968 | BJ74: =+BK74-BL74 -> 46359 | BK74: =+BQ74 -> 46359 | BL74: 0 | BM74: =+IF(BG74=0,BF74,BG74)+BL74 -> 391 | BO74: =+BM74-BK74 -> -45968 | BQ74: =+BR74-BS74 -> 46359 | BR74: =+BX74 -> 46366 | BS74: 7 | BT74: =+IF(BN74=0,BM74,BN74)+BS74 -> 398 | BV74: =+BT74-BR74 -> -45968 | BX74: 46366 | BY74: =+BT74-BX74 -> -45968 | CA74: Considero fecha de entrega de acuerdo a crono 4.11
A75: EL-Electricidad | C75: Tracing | E75: =+J75-1 -> 46138 | H75: =+F75-E75 -> -46138 | J75: =+K75-L75 -> 46139 | K75: =+R75-1 -> 46146 | L75: 7 | M75: =+F75+L75 -> 7 | O75: =+M75-K75 -> -46139 | R75: =+S75-T75 -> 46147 | S75: =+AC75-1 -> 46172 | T75: 25 | U75: =+M75+T75 -> 32 | W75: =+U75-S75 -> -46140 | AC75: =+AD75-AE75 -> 46173 | AD75: =+AJ75-1 -> 46203 | AE75: 30 | AF75: =+IF(V75=0,U75,V75)+AE75 -> 62 | AH75: =+AF75-AD75 -> -46141 | AJ75: =+AK75-AL75 -> 46204 | AK75: =+AV75-1 -> 46218 | AL75: 14 | AM75: =+IF(AG75=0,AF75,AG75)+AL75 -> 76 | AO75: =+AM75-AK75 -> -46142 | AV75: =+AW75-AX75 -> 46219 | AW75: =+BQ75-1 -> 46369 | AX75: 150 | AY75: =+IF(AN75=0,AM75,AN75)+AX75 -> 226 | BA75: =+AY75-AW75 -> -46143 | BC75: =+BD75-BE75 -> 46370 | BD75: =+BJ75 -> 46370 | BE75: 0 | BF75: =+IF(AZ75=0,AY75,AZ75)+BE75 -> 226 | BH75: =+BF75-BD75 -> -46144 | BJ75: =+BK75-BL75 -> 46370 | BK75: =+BQ75 -> 46370 | BL75: 0 | BM75: =+IF(BG75=0,BF75,BG75)+BL75 -> 226 | BO75: =+BM75-BK75 -> -46144 | BQ75: =+BR75-BS75 -> 46370 | BR75: =+BX75 -> 46377 | BS75: 7 | BT75: =+IF(BN75=0,BM75,BN75)+BS75 -> 233 | BV75: =+BT75-BR75 -> -46144 | BX75: 46377 | BY75: =+BT75-BX75 -> -46144 | CA75: Considero fecha de entrega de acuerdo a crono 4.11
A76: EL-Electricidad | C76: Ducto de barras | E76: =+J76-1 -> 45912 | H76: =+F76-E76 -> -45912 | J76: =+K76-L76 -> 45913 | K76: =+R76-1 -> 45920 | L76: 7 | M76: =+F76+L76 -> 7 | O76: =+M76-K76 -> -45913 | R76: =+S76-T76 -> 45921 | S76: =+AC76-1 -> 45946 | T76: 25 | U76: =+M76+T76 -> 32 | W76: =+U76-S76 -> -45914 | AC76: =+AD76-AE76 -> 45947 | AD76: =+AJ76-1 -> 45992 | AE76: 45 | AF76: =+IF(V76=0,U76,V76)+AE76 -> 77 | AH76: =+AF76-AD76 -> -45915 | AJ76: =+AK76-AL76 -> 45993 | AK76: =+AV76-1 -> 46007 | AL76: 14 | AM76: =+IF(AG76=0,AF76,AG76)+AL76 -> 91 | AO76: =+AM76-AK76 -> -45916 | AV76: =+AW76-AX76 -> 46008 | AW76: =+BQ76-1 -> 46308 | AX76: 300 | AY76: =+IF(AN76=0,AM76,AN76)+AX76 -> 391 | BA76: =+AY76-AW76 -> -45917 | BC76: =+BD76-BE76 -> 46309 | BD76: =+BJ76 -> 46309 | BE76: 0 | BF76: =+IF(AZ76=0,AY76,AZ76)+BE76 -> 391 | BH76: =+BF76-BD76 -> -45918 | BJ76: =+BK76-BL76 -> 46309 | BK76: =+BQ76 -> 46309 | BL76: 0 | BM76: =+IF(BG76=0,BF76,BG76)+BL76 -> 391 | BO76: =+BM76-BK76 -> -45918 | BQ76: =+BR76-BS76 -> 46309 | BR76: =+BX76 -> 46316 | BS76: 7 | BT76: =+IF(BN76=0,BM76,BN76)+BS76 -> 398 | BV76: =+BT76-BR76 -> -45918 | BX76: 46316 | BY76: =+BT76-BX76 -> -45918 | CA76: Considero fecha de entrega de CCM y Tablero BT de acuerdo a crono 4.11
A77: PI-Piping | C77: Cañerías y accesorios - Rev. 0 - OC a 150 días Hito 2 | E77: =+J77-1 -> 45739 | F77: =+C82+60 -> 45748 | H77: =+F77-E77 -> 9 | J77: =+K77-L77 -> 45740 | K77: =+R77-1 -> 45747 | L77: 7 | M77: =+F77+L77 -> 45755 | O77: =+M77-K77 -> 8 | R77: =+S77-T77 -> 45748 | S77: =+AC77-1 -> 45773 | T77: 25 | U77: =+M77+T77 -> 45780 | W77: =+U77-S77 -> 7 | AC77: =+AD77-AE77 -> 45774 | AD77: =+AJ77-1 -> 45774 | AF77: =+IF(V77=0,U77,V77)+AE77 -> 45780 | AH77: =+AF77-AD77 -> 6 | AJ77: =+AK77-AL77 -> 45775 | AK77: =+AV77-1 -> 45789 | AL77: 14 | AM77: =+IF(AG77=0,AF77,AG77)+AL77 -> 45794 | AO77: =+AM77-AK77 -> 5 | AV77: =+AW77-AX77 -> 45790 | AW77: =+BC77 -> 45865 | AX77: 75 | AY77: =+IF(AN77=0,AM77,AN77)+AX77 -> 45869 | BA77: =+AY77-AW77 -> 4 | BC77: =+BD77-BE77 -> 45865 | BD77: =+BJ77 -> 45955 | BE77: 90 | BF77: =+IF(AZ77=0,AY77,AZ77)+BE77 -> 45959 | BH77: =+BF77-BD77 -> 4 | BJ77: =+BK77-BL77 -> 45955 | BK77: =+BQ77 -> 45965 | BL77: 10 | BM77: =+IF(BG77=0,BF77,BG77)+BL77 -> 45969 | BO77: =+BM77-BK77 -> 4 | BQ77: =+BR77-BS77 -> 45965 | BR77: =+BX77 -> 45972 | BS77: 7 | BT77: =+IF(BN77=0,BM77,BN77)+BS77 -> 45976 | BV77: =+BT77-BR77 -> 4 | BX77: 45972 | BY77: =+BT77-BX77 -> 4 | CA77: Considero fecha de entrega de suministro temprano de piping de crono A8910
A78: PI-Piping | C78: Cañerías y accesorios - Rev. 1 - Ingeniería 80% | E78: =+J78-1 -> 45875 | F78: =+F72 -> 46168 | H78: =+F78-E78 -> 293 | J78: =+K78-L78 -> 45876 | K78: =+R78-1 -> 45883 | L78: 7 | M78: =+F78+L78 -> 46175 | O78: =+M78-K78 -> 292 | R78: =+S78-T78 -> 45884 | S78: =+AC78-1 -> 45909 | T78: 25 | U78: =+M78+T78 -> 46200 | W78: =+U78-S78 -> 291 | AC78: =+AD78-AE78 -> 45910 | AD78: =+AJ78-1 -> 45910 | AF78: =+IF(V78=0,U78,V78)+AE78 -> 46200 | AH78: =+AF78-AD78 -> 290 | AJ78: =+AK78-AL78 -> 45911 | AK78: =+AV78-1 -> 45925 | AL78: 14 | AM78: =+IF(AG78=0,AF78,AG78)+AL78 -> 46214 | AO78: =+AM78-AK78 -> 289 | AV78: =+AW78-AX78 -> 45926 | AW78: =+BQ78-1 -> 46001 | AX78: 75 | AY78: =+IF(AN78=0,AM78,AN78)+AX78 -> 46289 | BA78: =+AY78-AW78 -> 288 | BC78: =+BD78-BE78 -> 45962 | BD78: =+BJ78 -> 45992 | BE78: 30 | BF78: =+IF(AZ78=0,AY78,AZ78)+BE78 -> 46319 | BH78: =+BF78-BD78 -> 327 | BJ78: =+BK78-BL78 -> 45992 | BK78: =+BQ78 -> 46002 | BL78: 10 | BM78: =+IF(BG78=0,BF78,BG78)+BL78 -> 46329 | BO78: =+BM78-BK78 -> 327 | BQ78: =+BR78-BS78 -> 46002 | BR78: =+BX78 -> 46009 | BS78: 7 | BT78: =+IF(BN78=0,BM78,BN78)+BS78 -> 46336 | BV78: =+BT78-BR78 -> 327 | BX78: 46009 | BY78: =+BT78-BX78 -> 327 | CA78: Considero fecha de fin de entrega piping de crono 4.11 - Coincide con inicio de prefa
A79: PI-Piping | C79: Válvulas manuales - Rev. 0 - Ingeniería inicial | E79: =+J79-1 -> 46140 | H79: =+F79-E79 -> -46140 | J79: =+K79-L79 -> 46141 | K79: =+R79-1 -> 46148 | L79: 7 | M79: =+F79+L79 -> 7 | O79: =+M79-K79 -> -46141 | R79: =+S79-T79 -> 46149 | S79: =+AC79-1 -> 46174 | T79: 25 | U79: =+M79+T79 -> 32 | W79: =+U79-S79 -> -46142 | AC79: =+AD79-AE79 -> 46175 | AD79: =+AJ79-1 -> 46220 | AE79: 45 | AF79: =+IF(V79=0,U79,V79)+AE79 -> 77 | AH79: =+AF79-AD79 -> -46143 | AJ79: =+AK79-AL79 -> 46221 | AK79: =+AV79-1 -> 46235 | AL79: 14 | AM79: =+IF(AG79=0,AF79,AG79)+AL79 -> 91 | AO79: =+AM79-AK79 -> -46144 | AV79: =+AW79-AX79 -> 46236 | AW79: =+BQ79-1 -> 46386 | AX79: 150 | AY79: =+IF(AN79=0,AM79,AN79)+AX79 -> 241 | BA79: =+AY79-AW79 -> -46145 | BC79: =+BD79-BE79 -> 46287 | BD79: =+BJ79 -> 46377 | BE79: 90 | BF79: =+IF(AZ79=0,AY79,AZ79)+BE79 -> 331 | BH79: =+BF79-BD79 -> -46046 | BJ79: =+BK79-BL79 -> 46377 | BK79: =+BQ79 -> 46387 | BL79: 10 | BM79: =+IF(BG79=0,BF79,BG79)+BL79 -> 341 | BO79: =+BM79-BK79 -> -46046 | BQ79: =+BR79-BS79 -> 46387 | BR79: =+BX79 -> 46394 | BS79: 7 | BT79: =+IF(BN79=0,BM79,BN79)+BS79 -> 348 | BV79: =+BT79-BR79 -> -46046 | BX79: 46394 | BY79: =+BT79-BX79 -> -46046 | CA79: Considero fecha de fin de entrega piping de crono 4.11
